Workbook

Sheet KUMAŞ SİPARİŞ FORMU
B2: SİPARİŞ FORMU | D2: KUMAŞ SİPARİŞ FORMU | K2: ÜRETİM ÖZET | Q2: ÜRETİM ORANI
B4: SİPARİŞ NO | F4: SİPARİŞ TARİHİ
B5: MÜŞTERİ | F5: TERMİN TARİHİ
B7: ÜRÜN KOD | C7: ÜRÜN ADI | G7: RENK | H7: KUMAŞ ENİ | I7: ADET/MT | K7: DOK. | L7: KESİM | M7: Y.SEVK | N7: 1.K | O7: 2.K | P7: YÜK | Q7: DOK. | R7: KESİM | S7: Y.SEVK | T7: 1.K | U7: 2.K | V7: YÜK
B8: 1 | K8: ='Genel Durum'!J3 -> 0 | L8: ='Genel Durum'!Q3 -> 0 | M8: ='Genel Durum'!AC3 -> 0 | N8: ='Genel Durum'!AO3 -> 0 | O8: ='Genel Durum'!AZ3 -> 0 | P8: ='Genel Durum'!BK3 -> 0 | Q8: =IFERROR(K8/$I8,0) -> 0 | R8: =IFERROR(L8/$I8,0) -> 0 | S8: =IFERROR(M8/$I8,0) -> 0 | T8: =IFERROR(N8/$I8,0) -> 0 | U8: =IFERROR(O8/$I8,0) -> 0 | V8: =IFERROR(P8/$I8,0) -> 0
B9: 2 | K9: ='Genel Durum'!J4 -> 0 | L9: ='Genel Durum'!Q4 -> 0 | M9: ='Genel Durum'!AC4 -> 0 | N9: ='Genel Durum'!AO4 -> 0 | O9: ='Genel Durum'!AZ4 -> 0 | P9: ='Genel Durum'!BK4 -> 0 | Q9: =IFERROR(K9/$I9,0) -> 0 | R9: =IFERROR(L9/$I9,0) -> 0 | S9: =IFERROR(M9/$I9,0) -> 0 | T9: =IFERROR(N9/$I9,0) -> 0 | U9: =IFERROR(O9/$I9,0) -> 0 | V9: =IFERROR(P9/$I9,0) -> 0
B10: 3 | K10: ='Genel Durum'!J5 -> 0 | L10: ='Genel Durum'!Q5 -> 0 | M10: ='Genel Durum'!AC5 -> 0 | N10: ='Genel Durum'!AO5 -> 0 | O10: ='Genel Durum'!AZ5 -> 0 | P10: ='Genel Durum'!BK5 -> 0 | Q10: =IFERROR(K10/$I10,0) -> 0 | R10: =IFERROR(L10/$I10,0) -> 0 | S10: =IFERROR(M10/$I10,0) -> 0 | T10: =IFERROR(N10/$I10,0) -> 0 | U10: =IFERROR(O10/$I10,0) -> 0 | V10: =IFERROR(P10/$I10,0) -> 0
B11: 4 | K11: ='Genel Durum'!J6 -> 0 | L11: ='Genel Durum'!Q6 -> 0 | M11: ='Genel Durum'!AC6 -> 0 | N11: ='Genel Durum'!AO6 -> 0 | O11: ='Genel Durum'!AZ6 -> 0 | P11: ='Genel Durum'!BK6 -> 0 | Q11: =IFERROR(K11/$I11,0) -> 0 | R11: =IFERROR(L11/$I11,0) -> 0 | S11: =IFERROR(M11/$I11,0) -> 0 | T11: =IFERROR(N11/$I11,0) -> 0 | U11: =IFERROR(O11/$I11,0) -> 0 | V11: =IFERROR(P11/$I11,0) -> 0
B12: 5 | K12: ='Genel Durum'!J7 -> 0 | L12: ='Genel Durum'!Q7 -> 0 | M12: ='Genel Durum'!AC7 -> 0 | N12: ='Genel Durum'!AO7 -> 0 | O12: ='Genel Durum'!AZ7 -> 0 | P12: ='Genel Durum'!BK7 -> 0 | Q12: =IFERROR(K12/$I12,0) -> 0 | R12: =IFERROR(L12/$I12,0) -> 0 | S12: =IFERROR(M12/$I12,0) -> 0 | T12: =IFERROR(N12/$I12,0) -> 0 | U12: =IFERROR(O12/$I12,0) -> 0 | V12: =IFERROR(P12/$I12,0) -> 0
B13: 6 | K13: ='Genel Durum'!J8 -> 0 | L13: ='Genel Durum'!Q8 -> 0 | M13: ='Genel Durum'!AC8 -> 0 | N13: ='Genel Durum'!AO8 -> 0 | O13: ='Genel Durum'!AZ8 -> 0 | P13: ='Genel Durum'!BK8 -> 0 | Q13: =IFERROR(K13/$I13,0) -> 0 | R13: =IFERROR(L13/$I13,0) -> 0 | S13: =IFERROR(M13/$I13,0) -> 0 | T13: =IFERROR(N13/$I13,0) -> 0 | U13: =IFERROR(O13/$I13,0) -> 0 | V13: =IFERROR(P13/$I13,0) -> 0
B14: 7 | K14: ='Genel Durum'!J9 -> 0 | L14: ='Genel Durum'!Q9 -> 0 | M14: ='Genel Durum'!AC9 -> 0 | N14: ='Genel Durum'!AO9 -> 0 | O14: ='Genel Durum'!AZ9 -> 0 | P14: ='Genel Durum'!BK9 -> 0 | Q14: =IFERROR(K14/$I14,0) -> 0 | R14: =IFERROR(L14/$I14,0) -> 0 | S14: =IFERROR(M14/$I14,0) -> 0 | T14: =IFERROR(N14/$I14,0) -> 0 | U14: =IFERROR(O14/$I14,0) -> 0 | V14: =IFERROR(P14/$I14,0) -> 0
B15: 8 | K15: ='Genel Durum'!J10 -> 0 | L15: ='Genel Durum'!Q10 -> 0 | M15: ='Genel Durum'!AC10 -> 0 | N15: ='Genel Durum'!AO10 -> 0 | O15: ='Genel Durum'!AZ10 -> 0 | P15: ='Genel Durum'!BK10 -> 0 | Q15: =IFERROR(K15/$I15,0) -> 0 | R15: =IFERROR(L15/$I15,0) -> 0 | S15: =IFERROR(M15/$I15,0) -> 0 | T15: =IFERROR(N15/$I15,0) -> 0 | U15: =IFERROR(O15/$I15,0) -> 0 | V15: =IFERROR(P15/$I15,0) -> 0
B16: 9 | K16: ='Genel Durum'!J11 -> 0 | L16: ='Genel Durum'!Q11 -> 0 | M16: ='Genel Durum'!AC11 -> 0 | N16: ='Genel Durum'!AO11 -> 0 | O16: ='Genel Durum'!AZ11 -> 0 | P16: ='Genel Durum'!BK11 -> 0 | Q16: =IFERROR(K16/$I16,0) -> 0 | R16: =IFERROR(L16/$I16,0) -> 0 | S16: =IFERROR(M16/$I16,0) -> 0 | T16: =IFERROR(N16/$I16,0) -> 0 | U16: =IFERROR(O16/$I16,0) -> 0 | V16: =IFERROR(P16/$I16,0) -> 0
B17: 10 | K17: ='Genel Durum'!J12 -> 0 | L17: ='Genel Durum'!Q12 -> 0 | M17: ='Genel Durum'!AC12 -> 0 | N17: ='Genel Durum'!AO12 -> 0 | O17: ='Genel Durum'!AZ12 -> 0 | P17: ='Genel Durum'!BK12 -> 0 | Q17: =IFERROR(K17/$I17,0) -> 0 | R17: =IFERROR(L17/$I17,0) -> 0 | S17: =IFERROR(M17/$I17,0) -> 0 | T17: =IFERROR(N17/$I17,0) -> 0 | U17: =IFERROR(O17/$I17,0) -> 0 | V17: =IFERROR(P17/$I17,0) -> 0
B19: ÜRETİM DETAYLARI
B20: TARAK NO | F20: TARAK ENİ
B21: ÇÖZGÜ SIKLIĞI | F21: ÇÖZGÜ İPİ
B22: ATKI SIKLIĞI | F22: ATKI İPİ
B24: KULLANILACAK RENK BİLGİLERİ
B25: RENK | D25: RENK KODU | F25: RENK | H25: RENK KODU
B32: NOTLAR

Sheet SİPARİŞ FORMU
B2: SİPARİŞ FORMU | D2: SİPARİŞ FORMU | K2: ÜRETİM ÖZET | Q2: ÜRETİM ORANI
B4: SİPARİŞ NO | F4: SİPARİŞ TARİHİ
B5: MÜŞTERİ | F5: TERMİN TARİHİ
B7: ÜRÜN KOD | C7: ÜRÜN ADI | G7: RENK | H7: EBAT | I7: ADET/MT | K7: DOK. | L7: KESİM | M7: Y.SEVK | N7: 1.K | O7: 2.K | P7: YÜK | Q7: DOK. | R7: KESİM | S7: Y.SEVK | T7: 1.K | U7: 2.K | V7: YÜK
B8: 1 | K8: ='Genel Durum'!J3 -> 0 | L8: ='Genel Durum'!Q3 -> 0 | M8: ='Genel Durum'!AC3 -> 0 | N8: ='Genel Durum'!AO3 -> 0 | O8: ='Genel Durum'!AZ3 -> 0 | P8: ='Genel Durum'!BK3 -> 0 | Q8: =IFERROR(K8/$I8,0) -> 0 | R8: =IFERROR(L8/$I8,0) -> 0 | S8: =IFERROR(M8/$I8,0) -> 0 | T8: =IFERROR(N8/$I8,0) -> 0 | U8: =IFERROR(O8/$I8,0) -> 0 | V8: =IFERROR(P8/$I8,0) -> 0
B9: 2 | K9: ='Genel Durum'!J4 -> 0 | L9: ='Genel Durum'!Q4 -> 0 | M9: ='Genel Durum'!AC4 -> 0 | N9: ='Genel Durum'!AO4 -> 0 | O9: ='Genel Durum'!AZ4 -> 0 | P9: ='Genel Durum'!BK4 -> 0 | Q9: =IFERROR(K9/$I9,0) -> 0 | R9: =IFERROR(L9/$I9,0) -> 0 | S9: =IFERROR(M9/$I9,0) -> 0 | T9: =IFERROR(N9/$I9,0) -> 0 | U9: =IFERROR(O9/$I9,0) -> 0 | V9: =IFERROR(P9/$I9,0) -> 0
B10: 3 | K10: ='Genel Durum'!J5 -> 0 | L10: ='Genel Durum'!Q5 -> 0 | M10: ='Genel Durum'!AC5 -> 0 | N10: ='Genel Durum'!AO5 -> 0 | O10: ='Genel Durum'!AZ5 -> 0 | P10: ='Genel Durum'!BK5 -> 0 | Q10: =IFERROR(K10/$I10,0) -> 0 | R10: =IFERROR(L10/$I10,0) -> 0 | S10: =IFERROR(M10/$I10,0) -> 0 | T10: =IFERROR(N10/$I10,0) -> 0 | U10: =IFERROR(O10/$I10,0) -> 0 | V10: =IFERROR(P10/$I10,0) -> 0
B11: 4 | K11: ='Genel Durum'!J6 -> 0 | L11: ='Genel Durum'!Q6 -> 0 | M11: ='Genel Durum'!AC6 -> 0 | N11: ='Genel Durum'!AO6 -> 0 | O11: ='Genel Durum'!AZ6 -> 0 | P11: ='Genel Durum'!BK6 -> 0 | Q11: =IFERROR(K11/$I11,0) -> 0 | R11: =IFERROR(L11/$I11,0) -> 0 | S11: =IFERROR(M11/$I11,0) -> 0 | T11: =IFERROR(N11/$I11,0) -> 0 | U11: =IFERROR(O11/$I11,0) -> 0 | V11: =IFERROR(P11/$I11,0) -> 0
B12: 5 | K12: ='Genel Durum'!J7 -> 0 | L12: ='Genel Durum'!Q7 -> 0 | M12: ='Genel Durum'!AC7 -> 0 | N12: ='Genel Durum'!AO7 -> 0 | O12: ='Genel Durum'!AZ7 -> 0 | P12: ='Genel Durum'!BK7 -> 0 | Q12: =IFERROR(K12/$I12,0) -> 0 | R12: =IFERROR(L12/$I12,0) -> 0 | S12: =IFERROR(M12/$I12,0) -> 0 | T12: =IFERROR(N12/$I12,0) -> 0 | U12: =IFERROR(O12/$I12,0) -> 0 | V12: =IFERROR(P12/$I12,0) -> 0
B13: 6 | K13: ='Genel Durum'!J8 -> 0 | L13: ='Genel Durum'!Q8 -> 0 | M13: ='Genel Durum'!AC8 -> 0 | N13: ='Genel Durum'!AO8 -> 0 | O13: ='Genel Durum'!AZ8 -> 0 | P13: ='Genel Durum'!BK8 -> 0 | Q13: =IFERROR(K13/$I13,0) -> 0 | R13: =IFERROR(L13/$I13,0) -> 0 | S13: =IFERROR(M13/$I13,0) -> 0 | T13: =IFERROR(N13/$I13,0) -> 0 | U13: =IFERROR(O13/$I13,0) -> 0 | V13: =IFERROR(P13/$I13,0) -> 0
B14: 7 | K14: ='Genel Durum'!J9 -> 0 | L14: ='Genel Durum'!Q9 -> 0 | M14: ='Genel Durum'!AC9 -> 0 | N14: ='Genel Durum'!AO9 -> 0 | O14: ='Genel Durum'!AZ9 -> 0 | P14: ='Genel Durum'!BK9 -> 0 | Q14: =IFERROR(K14/$I14,0) -> 0 | R14: =IFERROR(L14/$I14,0) -> 0 | S14: =IFERROR(M14/$I14,0) -> 0 | T14: =IFERROR(N14/$I14,0) -> 0 | U14: =IFERROR(O14/$I14,0) -> 0 | V14: =IFERROR(P14/$I14,0) -> 0
B15: 8 | K15: ='Genel Durum'!J10 -> 0 | L15: ='Genel Durum'!Q10 -> 0 | M15: ='Genel Durum'!AC10 -> 0 | N15: ='Genel Durum'!AO10 -> 0 | O15: ='Genel Durum'!AZ10 -> 0 | P15: ='Genel Durum'!BK10 -> 0 | Q15: =IFERROR(K15/$I15,0) -> 0 | R15: =IFERROR(L15/$I15,0) -> 0 | S15: =IFERROR(M15/$I15,0) -> 0 | T15: =IFERROR(N15/$I15,0) -> 0 | U15: =IFERROR(O15/$I15,0) -> 0 | V15: =IFERROR(P15/$I15,0) -> 0
B16: 9 | K16: ='Genel Durum'!J11 -> 0 | L16: ='Genel Durum'!Q11 -> 0 | M16: ='Genel Durum'!AC11 -> 0 | N16: ='Genel Durum'!AO11 -> 0 | O16: ='Genel Durum'!AZ11 -> 0 | P16: ='Genel Durum'!BK11 -> 0 | Q16: =IFERROR(K16/$I16,0) -> 0 | R16: =IFERROR(L16/$I16,0) -> 0 | S16: =IFERROR(M16/$I16,0) -> 0 | T16: =IFERROR(N16/$I16,0) -> 0 | U16: =IFERROR(O16/$I16,0) -> 0 | V16: =IFERROR(P16/$I16,0) -> 0
B17: 10 | K17: ='Genel Durum'!J12 -> 0 | L17: ='Genel Durum'!Q12 -> 0 | M17: ='Genel Durum'!AC12 -> 0 | N17: ='Genel Durum'!AO12 -> 0 | O17: ='Genel Durum'!AZ12 -> 0 | P17: ='Genel Durum'!BK12 -> 0 | Q17: =IFERROR(K17/$I17,0) -> 0 | R17: =IFERROR(L17/$I17,0) -> 0 | S17: =IFERROR(M17/$I17,0) -> 0 | T17: =IFERROR(N17/$I17,0) -> 0 | U17: =IFERROR(O17/$I17,0) -> 0 | V17: =IFERROR(P17/$I17,0) -> 0
B18: 11 | K18: ='Genel Durum'!J13 -> 0 | L18: ='Genel Durum'!Q13 -> 0 | M18: ='Genel Durum'!AC13 -> 0 | N18: ='Genel Durum'!AO13 -> 0 | O18: ='Genel Durum'!AZ13 -> 0 | P18: ='Genel Durum'!BK13 -> 0 | Q18: =IFERROR(K18/$I18,0) -> 0 | R18: =IFERROR(L18/$I18,0) -> 0 | S18: =IFERROR(M18/$I18,0) -> 0 | T18: =IFERROR(N18/$I18,0) -> 0 | U18: =IFERROR(O18/$I18,0) -> 0 | V18: =IFERROR(P18/$I18,0) -> 0
B19: 12 | K19: ='Genel Durum'!J14 -> 0 | L19: ='Genel Durum'!Q14 -> 0 | M19: ='Genel Durum'!AC14 -> 0 | N19: ='Genel Durum'!AO14 -> 0 | O19: ='Genel Durum'!AZ14 -> 0 | P19: ='Genel Durum'!BK14 -> 0 | Q19: =IFERROR(K19/$I19,0) -> 0 | R19: =IFERROR(L19/$I19,0) -> 0 | S19: =IFERROR(M19/$I19,0) -> 0 | T19: =IFERROR(N19/$I19,0) -> 0 | U19: =IFERROR(O19/$I19,0) -> 0 | V19: =IFERROR(P19/$I19,0) -> 0
... B37: 30 | K37: ='Genel Durum'!J32 -> 0 | L37: ='Genel Durum'!Q32 -> 0 | M37: ='Genel Durum'!AC32 -> 0 | N37: ='Genel Durum'!AO32 -> 0 | O37: ='Genel Durum'!AZ32 -> 0 | P37: ='Genel Durum'!BK32 -> 0 | Q37: =IFERROR(K37/$I37,0) -> 0 | R37: =IFERROR(L37/$I37,0) -> 0 | S37: =IFERROR(M37/$I37,0) -> 0 | T37: =IFERROR(N37/$I37,0) -> 0 | U37: =IFERROR(O37/$I37,0) -> 0 | V37: =IFERROR(P37/$I37,0) -> 0
B39: ÜRÜN GÖRSELLERİ
B56: ÜRETİM DETAYLARI
B57: TARAK NO | F57: TARAK ENİ
B58: ÇÖZGÜ SIKLIĞI | F58: ÇÖZGÜ İPİ
B59: ATKI SIKLIĞI | F59: ATKI İPİ
B61: KULLANILACAK RENK BİLGİLERİ
B62: RENK | D62: RENK KODU | F62: RENK | H62: RENK KODU
B69: NOTLAR

Sheet Pastal

Sheet Kesim Ölçüleri

Sheet Genel Durum
B1: SİPARİŞ BİLGİLERİ | J1: DOKUMA VERİLERİ
B2: ÜRÜN KOD | C2: ÜRÜN ADI | G2: RENK | H2: EBAT | I2: SİPARİŞ | J2: Toplam Dokunan Mt | K2: Toplam Dokunan Ad/Kg | L2: Sevk Mt | M2: Sevk Ad/Kg | N2: Dokuma Stok Metre | O2: Dokuma Stok Ad/Kg | P2: Üretim Durumu | Q2: KESİM | AC2: YIKAMA SEVK | AO2: 1. KALİTE | AZ2: 2. KALİTE | BK2: YÜKLEME
B3: 1 | C3: ='SİPARİŞ FORMU'!$C8 -> 0 | G3: ='SİPARİŞ FORMU'!$G8 -> 0 | H3: ='SİPARİŞ FORMU'!$H8 -> 0 | I3: ='SİPARİŞ FORMU'!$I8 -> 0 | J3: =No.1!$D$9 -> 0 | K3: =No.1!$D$10 -> 0 | L3: =No.1!$D$12 -> 0 | M3: =No.1!$D$13 -> 0 | N3: =J3-L3 -> 0 | O3: =K3-M3 -> 0 | P3: =J3/I3 -> #DIV/0! | Q3: =SUM(R3:AB3) -> 0 | AC3: =SUM(AD3:AN3) -> 0 | AO3: =SUM(AP3:AY3) -> 0
B4: 2 | C4: ='SİPARİŞ FORMU'!$C9 -> 0 | G4: ='SİPARİŞ FORMU'!$G9 -> 0 | H4: ='SİPARİŞ FORMU'!$H9 -> 0 | I4: ='SİPARİŞ FORMU'!$I9 -> 0 | J4: =No.2!$D$9 -> 0 | K4: =No.2!$D$10 -> 0 | L4: =No.2!$D$12 -> 0 | M4: =No.2!$D$13 -> 0 | N4: =J4-L4 -> 0 | O4: =K4-M4 -> 0 | P4: =J4/I4 -> #DIV/0! | Q4: =SUM(R4:AB4) -> 0 | AC4: =SUM(AD4:AN4) -> 0 | AO4: =SUM(AP4:AY4) -> 0
B5: 3 | C5: ='SİPARİŞ FORMU'!$C10 -> 0 | G5: ='SİPARİŞ FORMU'!$G10 -> 0 | H5: ='SİPARİŞ FORMU'!$H10 -> 0 | I5: ='SİPARİŞ FORMU'!$I10 -> 0 | J5: =No.3!$D$9 -> 0 | K5: =No.3!$D$10 -> 0 | L5: =No.3!$D$12 -> 0 | M5: =No.3!$D$13 -> 0 | N5: =J5-L5 -> 0 | O5: =K5-M5 -> 0 | P5: =J5/I5 -> #DIV/0! | Q5: =SUM(R5:AB5) -> 0 | AC5: =SUM(AD5:AN5) -> 0 | AO5: =SUM(AP5:AY5) -> 0
B6: 4 | C6: ='SİPARİŞ FORMU'!$C11 -> 0 | G6: ='SİPARİŞ FORMU'!$G11 -> 0 | H6: ='SİPARİŞ FORMU'!$H11 -> 0 | I6: ='SİPARİŞ FORMU'!$I11 -> 0 | J6: =No.4!$D$9 -> 0 | K6: =No.4!$D$10 -> 0 | L6: =No.4!$D$12 -> 0 | M6: =No.4!$D$13 -> 0 | N6: =J6-L6 -> 0 | O6: =K6-M6 -> 0 | P6: =J6/I6 -> #DIV/0! | Q6: =SUM(R6:AB6) -> 0 | AC6: =SUM(AD6:AN6) -> 0 | AO6: =SUM(AP6:AY6) -> 0
B7: 5 | C7: ='SİPARİŞ FORMU'!$C12 -> 0 | G7: ='SİPARİŞ FORMU'!$G12 -> 0 | H7: ='SİPARİŞ FORMU'!$H12 -> 0 | I7: ='SİPARİŞ FORMU'!$I12 -> 0 | J7: =No.5!$D$9 -> 0 | K7: =No.5!$D$10 -> 0 | L7: =No.5!$D$12 -> 0 | M7: =No.5!$D$13 -> 0 | N7: =J7-L7 -> 0 | O7: =K7-M7 -> 0 | P7: =J7/I7 -> #DIV/0! | Q7: =SUM(R7:AB7) -> 0 | AC7: =SUM(AD7:AN7) -> 0 | AO7: =SUM(AP7:AY7) -> 0
B8: 6 | C8: ='SİPARİŞ FORMU'!$C13 -> 0 | G8: ='SİPARİŞ FORMU'!$G13 -> 0 | H8: ='SİPARİŞ FORMU'!$H13 -> 0 | I8: ='SİPARİŞ FORMU'!$I13 -> 0 | J8: =No.6!$D$9 -> 0 | K8: =No.6!$D$10 -> 0 | L8: =No.6!$D$12 -> 0 | M8: =No.6!$D$13 -> 0 | N8: =J8-L8 -> 0 | O8: =K8-M8 -> 0 | P8: =J8/I8 -> #DIV/0! | Q8: =SUM(R8:AB8) -> 0 | AC8: =SUM(AD8:AN8) -> 0 | AO8: =SUM(AP8:AY8) -> 0
B9: 7 | C9: ='SİPARİŞ FORMU'!$C14 -> 0 | G9: ='SİPARİŞ FORMU'!$G14 -> 0 | H9: ='SİPARİŞ FORMU'!$H14 -> 0 | I9: ='SİPARİŞ FORMU'!$I14 -> 0 | J9: =No.7!$D$9 -> 0 | K9: =No.7!$D$10 -> 0 | L9: =No.7!$D$12 -> 0 | M9: =No.7!$D$13 -> 0 | N9: =J9-L9 -> 0 | O9: =K9-M9 -> 0 | P9: =J9/I9 -> #DIV/0! | Q9: =SUM(R9:AB9) -> 0 | AC9: =SUM(AD9:AN9) -> 0 | AO9: =SUM(AP9:AY9) -> 0
B10: 8 | C10: ='SİPARİŞ FORMU'!$C15 -> 0 | G10: ='SİPARİŞ FORMU'!$G15 -> 0 | H10: ='SİPARİŞ FORMU'!$H15 -> 0 | I10: ='SİPARİŞ FORMU'!$I15 -> 0 | J10: =No.8!$D$9 -> 0 | K10: =No.8!$D$10 -> 0 | L10: =No.8!$D$12 -> 0 | M10: =No.8!$D$13 -> 0 | N10: =J10-L10 -> 0 | O10: =K10-M10 -> 0 | P10: =J10/I10 -> #DIV/0! | Q10: =SUM(R10:AB10) -> 0 | AC10: =SUM(AD10:AN10) -> 0 | AO10: =SUM(AP10:AY10) -> 0
B11: 9 | C11: ='SİPARİŞ FORMU'!$C16 -> 0 | G11: ='SİPARİŞ FORMU'!$G16 -> 0 | H11: ='SİPARİŞ FORMU'!$H16 -> 0 | I11: ='SİPARİŞ FORMU'!$I16 -> 0 | J11: =No.9!$D$9 -> 0 | K11: =No.9!$D$10 -> 0 | L11: =No.9!$D$12 -> 0 | M11: =No.9!$D$13 -> 0 | N11: =J11-L11 -> 0 | O11: =K11-M11 -> 0 | P11: =J11/I11 -> #DIV/0! | Q11: =SUM(R11:AB11) -> 0 | AC11: =SUM(AD11:AN11) -> 0 | AO11: =SUM(AP11:AY11) -> 0
B12: 10 | C12: ='SİPARİŞ FORMU'!$C17 -> 0 | G12: ='SİPARİŞ FORMU'!$G17 -> 0 | H12: ='SİPARİŞ FORMU'!$H17 -> 0 | I12: ='SİPARİŞ FORMU'!$I17 -> 0 | J12: =No.10!$D$9 -> 0 | K12: =No.10!$D$10 -> 0 | L12: =No.10!$D$12 -> 0 | M12: =No.10!$D$13 -> 0 | N12: =J12-L12 -> 0 | O12: =K12-M12 -> 0 | P12: =J12/I12 -> #DIV/0! | Q12: =SUM(R12:AB12) -> 0 | AC12: =SUM(AD12:AN12) -> 0 | AO12: =SUM(AP12:AY12) -> 0
B13: 11 | C13: ='SİPARİŞ FORMU'!$C18 -> 0 | G13: ='SİPARİŞ FORMU'!$G18 -> 0 | H13: ='SİPARİŞ FORMU'!$H18 -> 0 | I13: ='SİPARİŞ FORMU'!$I18 -> 0 | J13: =No.11!$D$9 -> 0 | K13: =No.11!$D$10 -> 0 | L13: =No.11!$D$12 -> 0 | M13: =No.11!$D$13 -> 0 | N13: =J13-L13 -> 0 | O13: =K13-M13 -> 0 | P13: =J13/I13 -> #DIV/0! | Q13: =SUM(R13:AB13) -> 0 | AC13: =SUM(AD13:AN13) -> 0 | AO13: =SUM(AP13:AY13) -> 0
B14: 12 | C14: ='SİPARİŞ FORMU'!$C19 -> 0 | G14: ='SİPARİŞ FORMU'!$G19 -> 0 | H14: ='SİPARİŞ FORMU'!$H19 -> 0 | I14: ='SİPARİŞ FORMU'!$I19 -> 0 | J14: =No.12!$D$9 -> 0 | K14: =No.12!$D$10 -> 0 | L14: =No.12!$D$12 -> 0 | M14: =No.12!$D$13 -> 0 | N14: =J14-L14 -> 0 | O14: =K14-M14 -> 0 | P14: =J14/I14 -> #DIV/0! | Q14: =SUM(R14:AB14) -> 0 | AC14: =SUM(AD14:AN14) -> 0 | AO14: =SUM(AP14:AY14) -> 0
B15: 13 | C15: ='SİPARİŞ FORMU'!$C20 -> 0 | G15: ='SİPARİŞ FORMU'!$G20 -> 0 | H15: ='SİPARİŞ FORMU'!$H20 -> 0 | I15: ='SİPARİŞ FORMU'!$I20 -> 0 | J15: =No.13!$D$9 -> 0 | K15: =No.13!$D$10 -> 0 | L15: =No.13!$D$12 -> 0 | M15: =No.13!$D$13 -> 0 | N15: =J15-L15 -> 0 | O15: =K15-M15 -> 0 | P15: =J15/I15 -> #DIV/0! | Q15: =SUM(R15:AB15) -> 0 | AC15: =SUM(AD15:AN15) -> 0 | AO15: =SUM(AP15:AY15) -> 0
B16: 14 | C16: ='SİPARİŞ FORMU'!$C21 -> 0 | G16: ='SİPARİŞ FORMU'!$G21 -> 0 | H16: ='SİPARİŞ FORMU'!$H21 -> 0 | I16: ='SİPARİŞ FORMU'!$I21 -> 0 | J16: =No.14!$D$9 -> 0 | K16: =No.14!$D$10 -> 0 | L16: =No.14!$D$12 -> 0 | M16: =No.14!$D$13 -> 0 | N16: =J16-L16 -> 0 | O16: =K16-M16 -> 0 | P16: =J16/I16 -> #DIV/0! | Q16: =SUM(R16:AB16) -> 0 | AC16: =SUM(AD16:AN16) -> 0 | AO16: =SUM(AP16:AY16) -> 0
B17: 15 | C17: ='SİPARİŞ FORMU'!$C22 -> 0 | G17: ='SİPARİŞ FORMU'!$G22 -> 0 | H17: ='SİPARİŞ FORMU'!$H22 -> 0 | I17: ='SİPARİŞ FORMU'!$I22 -> 0 | J17: =No.15!$D$9 -> 0 | K17: =No.15!$D$10 -> 0 | L17: =No.15!$D$12 -> 0 | M17: =No.15!$D$13 -> 0 | N17: =J17-L17 -> 0 | O17: =K17-M17 -> 0 | P17: =J17/I17 -> #DIV/0! | Q17: =SUM(R17:AB17) -> 0 | AC17: =SUM(AD17:AN17) -> 0 | AO17: =SUM(AP17:AY17) -> 0
B18: 16 | C18: ='SİPARİŞ FORMU'!$C23 -> 0 | G18: ='SİPARİŞ FORMU'!$G23 -> 0 | H18: ='SİPARİŞ FORMU'!$H23 -> 0 | I18: ='SİPARİŞ FORMU'!$I23 -> 0 | J18: =No.16!$D$9 -> 0 | K18: =No.16!$D$10 -> 0 | L18: =No.16!$D$12 -> 0 | M18: =No.16!$D$13 -> 0 | N18: =J18-L18 -> 0 | O18: =K18-M18 -> 0 | P18: =J18/I18 -> #DIV/0! | Q18: =SUM(R18:AB18) -> 0 | AC18: =SUM(AD18:AN18) -> 0 | AO18: =SUM(AP18:AY18) -> 0
B19: 17 | C19: ='SİPARİŞ FORMU'!$C24 -> 0 | G19: ='SİPARİŞ FORMU'!$G24 -> 0 | H19: ='SİPARİŞ FORMU'!$H24 -> 0 | I19: ='SİPARİŞ FORMU'!$I24 -> 0 | J19: =No.17!$D$9 -> 0 | K19: =No.17!$D$10 -> 0 | L19: =No.17!$D$12 -> 0 | M19: =No.17!$D$13 -> 0 | N19: =J19-L19 -> 0 | O19: =K19-M19 -> 0 | P19: =J19/I19 -> #DIV/0! | Q19: =SUM(R19:AB19) -> 0 | AC19: =SUM(AD19:AN19) -> 0 | AO19: =SUM(AP19:AY19) -> 0
B20: 18 | C20: ='SİPARİŞ FORMU'!$C25 -> 0 | G20: ='SİPARİŞ FORMU'!$G25 -> 0 | H20: ='SİPARİŞ FORMU'!$H25 -> 0 | I20: ='SİPARİŞ FORMU'!$I25 -> 0 | J20: =No.18!$D$9 -> 0 | K20: =No.18!$D$10 -> 0 | L20: =No.18!$D$12 -> 0 | M20: =No.18!$D$13 -> 0 | N20: =J20-L20 -> 0 | O20: =K20-M20 -> 0 | P20: =J20/I20 -> #DIV/0! | Q20: =SUM(R20:AB20) -> 0 | AC20: =SUM(AD20:AN20) -> 0 | AO20: =SUM(AP20:AY20) -> 0
B21: 19 | C21: ='SİPARİŞ FORMU'!$C26 -> 0 | G21: ='SİPARİŞ FORMU'!$G26 -> 0 | H21: ='SİPARİŞ FORMU'!$H26 -> 0 | I21: ='SİPARİŞ FORMU'!$I26 -> 0 | J21: =No.19!$D$9 -> 0 | K21: =No.19!$D$10 -> 0 | L21: =No.19!$D$12 -> 0 | M21: =No.19!$D$13 -> 0 | N21: =J21-L21 -> 0 | O21: =K21-M21 -> 0 | P21: =J21/I21 -> #DIV/0! | Q21: =SUM(R21:AB21) -> 0 | AC21: =SUM(AD21:AN21) -> 0 | AO21: =SUM(AP21:AY21) -> 0
B22: 20 | C22: ='SİPARİŞ FORMU'!$C27 -> 0 | G22: ='SİPARİŞ FORMU'!$G27 -> 0 | H22: ='SİPARİŞ FORMU'!$H27 -> 0 | I22: ='SİPARİŞ FORMU'!$I27 -> 0 | J22: =No.20!$D$9 -> 0 | K22: =No.20!$D$10 -> 0 | L22: =No.20!$D$12 -> 0 | M22: =No.20!$D$13 -> 0 | N22: =J22-L22 -> 0 | P22: =J22/I22 -> #DIV/0! | Q22: =SUM(R22:AB22) -> 0 | AC22: =SUM(AD22:AN22) -> 0 | AO22: =SUM(AP22:AY22) -> 0
B23: 21 | C23: ='SİPARİŞ FORMU'!$C28 -> 0 | G23: ='SİPARİŞ FORMU'!$G28 -> 0 | H23: ='SİPARİŞ FORMU'!$H28 -> 0 | I23: ='SİPARİŞ FORMU'!$I28 -> 0 | J23: =No.21!$D$9 -> 0 | K23: =No.21!$D$10 -> 0 | L23: =No.21!$D$12 -> 0 | M23: =No.21!$D$13 -> 0 | N23: =J23-L23 -> 0 | O23: =K23-M23 -> 0 | P23: =J23/I23 -> #DIV/0! | Q23: =SUM(R23:AB23) -> 0 | AC23: =SUM(AD23:AN23) -> 0 | AO23: =SUM(AP23:AY23) -> 0
B24: 22 | C24: ='SİPARİŞ FORMU'!$C29 -> 0 | G24: ='SİPARİŞ FORMU'!$G29 -> 0 | H24: ='SİPARİŞ FORMU'!$H29 -> 0 | I24: ='SİPARİŞ FORMU'!$I29 -> 0 | J24: =No.22!$D$9 -> 0 | K24: =No.22!$D$10 -> 0 | L24: =No.22!$D$12 -> 0 | M24: =No.22!$D$13 -> 0 | N24: =J24-L24 -> 0 | O24: =K24-M24 -> 0 | P24: =J24/I24 -> #DIV/0! | Q24: =SUM(R24:AB24) -> 0 | AC24: =SUM(AD24:AN24) -> 0 | AO24: =SUM(AP24:AY24) -> 0
B25: 23 | C25: ='SİPARİŞ FORMU'!$C30 -> 0 | G25: ='SİPARİŞ FORMU'!$G30 -> 0 | H25: ='SİPARİŞ FORMU'!$H30 -> 0 | I25: ='SİPARİŞ FORMU'!$I30 -> 0 | J25: =No.23!$D$9 -> 0 | K25: =No.23!$D$10 -> 0 | L25: =No.23!$D$12 -> 0 | M25: =No.23!$D$13 -> 0 | N25: =J25-L25 -> 0 | O25: =K25-M25 -> 0 | P25: =J25/I25 -> #DIV/0! | Q25: =SUM(R25:AB25) -> 0 | AC25: =SUM(AD25:AN25) -> 0 | AO25: =SUM(AP25:AY25) -> 0
B26: 24 | C26: ='SİPARİŞ FORMU'!$C31 -> 0 | G26: ='SİPARİŞ FORMU'!$G31 -> 0 | H26: ='SİPARİŞ FORMU'!$H31 -> 0 | I26: ='SİPARİŞ FORMU'!$I31 -> 0 | J26: =No.24!$D$9 -> 0 | K26: =No.24!$D$10 -> 0 | L26: =No.24!$D$12 -> 0 | M26: =No.24!$D$13 -> 0 | N26: =J26-L26 -> 0 | O26: =K26-M26 -> 0 | P26: =J26/I26 -> #DIV/0! | Q26: =SUM(R26:AB26) -> 0 | AC26: =SUM(AD26:AN26) -> 0 | AO26: =SUM(AP26:AY26) -> 0
B27: 25 | C27: ='SİPARİŞ FORMU'!$C32 -> 0 | G27: ='SİPARİŞ FORMU'!$G32 -> 0 | H27: ='SİPARİŞ FORMU'!$H32 -> 0 | I27: ='SİPARİŞ FORMU'!$I32 -> 0 | J27: =No.25!$D$9 -> 0 | K27: =No.25!$D$10 -> 0 | L27: =No.25!$D$12 -> 0 | M27: =No.25!$D$13 -> 0 | N27: =J27-L27 -> 0 | O27: =K27-M27 -> 0 | P27: =J27/I27 -> #DIV/0! | Q27: =SUM(R27:AB27) -> 0 | AC27: =SUM(AD27:AN27) -> 0 | AO27: =SUM(AP27:AY27) -> 0
B28: 26 | C28: ='SİPARİŞ FORMU'!$C33 -> 0 | G28: ='SİPARİŞ FORMU'!$G33 -> 0 | H28: ='SİPARİŞ FORMU'!$H33 -> 0 | I28: ='SİPARİŞ FORMU'!$I33 -> 0 | J28: =No.26!$D$9 -> 0 | K28: =No.26!$D$10 -> 0 | L28: =No.26!$D$12 -> 0 | M28: =No.26!$D$13 -> 0 | N28: =J28-L28 -> 0 | O28: =K28-M28 -> 0 | P28: =J28/I28 -> #DIV/0! | Q28: =SUM(R28:AB28) -> 0 | AC28: =SUM(AD28:AN28) -> 0 | AO28: =SUM(AP28:AY28) -> 0
B29: 27 | C29: ='SİPARİŞ FORMU'!$C34 -> 0 | G29: ='SİPARİŞ FORMU'!$G34 -> 0 | H29: ='SİPARİŞ FORMU'!$H34 -> 0 | I29: ='SİPARİŞ FORMU'!$I34 -> 0 | J29: =No.27!$D$9 -> 0 | K29: =No.27!$D$10 -> 0 | L29: =No.27!$D$12 -> 0 | M29: =No.27!$D$13 -> 0 | N29: =J29-L29 -> 0 | O29: =K29-M29 -> 0 | P29: =J29/I29 -> #DIV/0! | Q29: =SUM(R29:AB29) -> 0 | AC29: =SUM(AD29:AN29) -> 0 | AO29: =SUM(AP29:AY29) -> 0
B30: 28 | C30: ='SİPARİŞ FORMU'!$C35 -> 0 | G30: ='SİPARİŞ FORMU'!$G35 -> 0 | H30: ='SİPARİŞ FORMU'!$H35 -> 0 | I30: ='SİPARİŞ FORMU'!$I35 -> 0 | J30: =No.28!$D$9 -> 0 | K30: =No.28!$D$10 -> 0 | L30: =No.28!$D$12 -> 0 | M30: =No.28!$D$13 -> 0 | N30: =J30-L30 -> 0 | O30: =K30-M30 -> 0 | P30: =J30/I30 -> #DIV/0! | Q30: =SUM(R30:AB30) -> 0 | AC30: =SUM(AD30:AN30) -> 0 | AO30: =SUM(AP30:AY30) -> 0
B31: 29 | C31: ='SİPARİŞ FORMU'!$C36 -> 0 | G31: ='SİPARİŞ FORMU'!$G36 -> 0 | H31: ='SİPARİŞ FORMU'!$H36 -> 0 | I31: ='SİPARİŞ FORMU'!$I36 -> 0 | J31: =No.29!$D$9 -> 0 | K31: =No.29!$D$10 -> 0 | L31: =No.29!$D$12 -> 0 | M31: =No.29!$D$13 -> 0 | N31: =J31-L31 -> 0 | O31: =K31-M31 -> 0 | P31: =J31/I31 -> #DIV/0! | Q31: =SUM(R31:AB31) -> 0 | AC31: =SUM(AD31:AN31) -> 0 | AO31: =SUM(AP31:AY31) -> 0
B32: 30 | C32: ='SİPARİŞ FORMU'!$C37 -> 0 | G32: ='SİPARİŞ FORMU'!$G37 -> 0 | H32: ='SİPARİŞ FORMU'!$H37 -> 0 | I32: ='SİPARİŞ FORMU'!$I37 -> 0 | J32: =No.30!$D$9 -> 0 | K32: =No.30!$D$10 -> 0 | L32: =No.30!$D$12 -> 0 | M32: =No.30!$D$13 -> 0 | N32: =J32-L32 -> 0 | O32: =K32-M32 -> 0 | P32: =J32/I32 -> #DIV/0! | Q32: =SUM(R32:AB32) -> 0 | AC32: =SUM(AD32:AN32) -> 0 | AO32: =SUM(AP32:AY32) -> 0
G36: DOKUMA
G37: KESİM
G38: YIKAMA GİDEN
G39: YIKAMA GELEN
G40: YÜKLEME
G41: KALİTE 1-2

Sheet No.1
B2: Ürün Kodu: | D2: ='Genel Durum'!B3 -> 1 | G2: ÜRETİM VERİLERİ | BR2: SEVK VERİLERİ
B3: Sipariş No: | D3: ='SİPARİŞ FORMU'!C4 -> 0 | BR3: Tarih | BS3: Sevk yeri | BT3: Sevk Metre | BU3: Sevk Ad/Kg | BV3: Sevk Top Sayısı | BW3: Çeki Listesi | BX3: Açıklama
B4: Müşteri: | D4: ='SİPARİŞ FORMU'!C5 -> 0 | G4: Tarih | H4: Metre | I4: Kg/Ad | J4: Top Sayısı | L4: Tarih | M4: Metre | N4: Kg/Ad | O4: Top Sayısı | Q4: Tarih | R4: Metre | S4: Kg/Ad | T4: Top Sayısı | V4: Tarih | W4: Metre | X4: Kg/Ad | Y4: Top Sayısı | AA4: Tarih | AB4: Metre | AC4: Kg/Ad | AD4: Top Sayısı | AF4: Tarih | AG4: Metre | AH4: Kg/Ad | AI4: Top Sayısı | AK4: Tarih | AL4: Metre | AM4: Kg/Ad | AN4: Top Sayısı | AP4: Tarih | AQ4: Metre | AR4: Kg/Ad | AS4: Top Sayısı | AU4: Tarih | AV4: Metre | AW4: Kg/Ad | AX4: Top Sayısı | AZ4: Tarih | BA4: Metre | BB4: Kg/Ad | BC4: Top Sayısı | BE4: Tarih | BF4: Metre | BG4: Kg/Ad | BH4: Top Sayısı | BJ4: Tarih | BK4: Metre | BL4: Kg/Ad | BM4: Top Sayısı
B5: Ürün Adı: | D5: ='SİPARİŞ FORMU'!C8 -> 0
B6: Renk: | D6: ='SİPARİŞ FORMU'!G8 -> 0
B7: Kumaş Eni: | D7: ='SİPARİŞ FORMU'!H8 -> 0
B8: Sipariş Mt/Ad: | D8: ='SİPARİŞ FORMU'!I8 -> 0
B9: Üretilen Metre | D9: =+H36+M36+R36+W36+AB36+AG36+AL36+AQ36+AV36+BA36+BF36+BK36 -> 0
B10: Üretilen Kg/Ad | D10: =+I36+N36+S36+X36+AC36+AH36+AM36+AR36+AW36+BB36+BG36+BL36 -> 0
B11: Üretilen Top Sayısı | D11: =+J36+O36+T36+Y36+AD36+AI36+AN36+AS36+AX36+BC36+BH36+BM36 -> 0
B12: Sevk Metre | D12: =BT39 -> 0
B13: Sevk Kg/Ad | D13: =BU39 -> 0
B14: Sevk Top Sayısı | D14: =BV39 -> 0
B15: Stok Metre | D15: =D9-D12 -> 0
B16: Stok Kg/Ad | D16: =D10-D13 -> 0
B17: Stok Top Sayısı | D17: =D11-D14 -> 0
B19: Üretim Durumu | D19: =D9/D8 -> #DIV/0!
G36: Toplam | H36: =SUM(H5:H35) -> 0 | I36: =SUM(I5:I35) -> 0 | J36: =SUM(J5:J35) -> 0 | L36: Toplam | M36: =SUM(M5:M35) -> 0 | N36: =SUM(N5:N35) -> 0 | O36: =SUM(O5:O35) -> 0 | Q36: Toplam | R36: =SUM(R5:R35) -> 0 | S36: =SUM(S5:S35) -> 0 | T36: =SUM(T5:T35) -> 0 | V36: Toplam | W36: =SUM(W5:W35) -> 0 | X36: =SUM(X5:X35) -> 0 | Y36: =SUM(Y5:Y35) -> 0 | AA36: Toplam | AB36: =SUM(AB5:AB35) -> 0 | AC36: =SUM(AC5:AC35) -> 0 | AD36: =SUM(AD5:AD35) -> 0 | AF36: Toplam | AG36: =SUM(AG5:AG35) -> 0 | AH36: =SUM(AH5:AH35) -> 0 | AI36: =SUM(AI5:AI35) -> 0 | AK36: Toplam | AL36: =SUM(AL5:AL35) -> 0 | AM36: =SUM(AM5:AM35) -> 0 | AN36: =SUM(AN5:AN35) -> 0 | AP36: Toplam | AQ36: =SUM(AQ5:AQ35) -> 0 | AR36: =SUM(AR5:AR35) -> 0 | AS36: =SUM(AS5:AS35) -> 0 | AU36: Toplam | AV36: =SUM(AV5:AV35) -> 0 | AW36: =SUM(AW5:AW35) -> 0 | AX36: =SUM(AX5:AX35) -> 0 | AZ36: Toplam | BA36: =SUM(BA5:BA35) -> 0 | BB36: =SUM(BB5:BB35) -> 0 | BC36: =SUM(BC5:BC35) -> 0 | BE36: Toplam | BF36: =SUM(BF5:BF35) -> 0 | BG36: =SUM(BG5:BG35) -> 0 | BH36: =SUM(BH5:BH35) -> 0 | BJ36: Toplam | BK36: =SUM(BK5:BK35) -> 0 | BL36: =SUM(BL5:BL35) -> 0 | BM36: =SUM(BM5:BM35) -> 0
BR39: Toplam | BT39: =SUM(BT5:BT36) -> 0 | BU39: =SUM(BU5:BU36) -> 0 | BV39: =SUM(BV5:BV36) -> 0

Sheet No.2
B2: Ürün Kodu: | D2: ='SİPARİŞ FORMU'!B9 -> 2 | G2: ÜRETİM VERİLERİ | BR2: SEVK VERİLERİ
B3: Sipariş No: | D3: ='SİPARİŞ FORMU'!C4 -> 0 | BR3: Tarih | BS3: Sevk yeri | BT3: Sevk Metre | BU3: Sevk Ad/Kg | BV3: Sevk Top Sayısı | BW3: Çeki Listesi | BX3: Açıklama
B4: Müşteri: | D4: ='SİPARİŞ FORMU'!C5 -> 0 | G4: Tarih | H4: Metre | I4: Kg/Ad | J4: Top Sayısı | L4: Tarih | M4: Metre | N4: Kg/Ad | O4: Top Sayısı | Q4: Tarih | R4: Metre | S4: Kg/Ad | T4: Top Sayısı | V4: Tarih | W4: Metre | X4: Kg/Ad | Y4: Top Sayısı | AA4: Tarih | AB4: Metre | AC4: Kg/Ad | AD4: Top Sayısı | AF4: Tarih | AG4: Metre | AH4: Kg/Ad | AI4: Top Sayısı | AK4: Tarih | AL4: Metre | AM4: Kg/Ad | AN4: Top Sayısı | AP4: Tarih | AQ4: Metre | AR4: Kg/Ad | AS4: Top Sayısı | AU4: Tarih | AV4: Metre | AW4: Kg/Ad | AX4: Top Sayısı | AZ4: Tarih | BA4: Metre | BB4: Kg/Ad | BC4: Top Sayısı | BE4: Tarih | BF4: Metre | BG4: Kg/Ad | BH4: Top Sayısı | BJ4: Tarih | BK4: Metre | BL4: Kg/Ad | BM4: Top Sayısı
B5: Ürün Adı: | D5: ='SİPARİŞ FORMU'!C9 -> 0
B6: Renk: | D6: ='SİPARİŞ FORMU'!G9 -> 0
B7: Kumaş Eni: | D7: ='SİPARİŞ FORMU'!H9 -> 0
B8: Sipariş Mt/Ad: | D8: ='SİPARİŞ FORMU'!I9 -> 0
B9: Üretilen Metre | D9: =+H36+M36+R36+W36+AB36+AG36+AL36+AQ36+AV36+BA36+BF36+BK36 -> 0
B10: Üretilen Kg/Ad | D10: =+I36+N36+S36+X36+AC36+AH36+AM36+AR36+AW36+BB36+BG36+BL36 -> 0
B11: Üretilen Top Sayısı | D11: =+J36+O36+T36+Y36+AD36+AI36+AN36+AS36+AX36+BC36+BH36+BM36 -> 0
B12: Sevk Metre | D12: =BT39 -> 0
B13: Sevk Kg/Ad | D13: =BU39 -> 0
B14: Sevk Top Sayısı | D14: =BV39 -> 0
B15: Stok Metre | D15: =D9-D12 -> 0
B16: Stok Kg/Ad | D16: =D10-D13 -> 0
B17: Stok Top Sayısı | D17: =D11-D14 -> 0
B19: Üretim Durumu | D19: =D9/D8 -> #DIV/0!
G36: Toplam | H36: =SUM(H5:H35) -> 0 | I36: =SUM(I5:I35) -> 0 | J36: =SUM(J5:J35) -> 0 | L36: Toplam | M36: =SUM(M5:M35) -> 0 | N36: =SUM(N5:N35) -> 0 | O36: =SUM(O5:O35) -> 0 | Q36: Toplam | R36: =SUM(R5:R35) -> 0 | S36: =SUM(S5:S35) -> 0 | T36: =SUM(T5:T35) -> 0 | V36: Toplam | W36: =SUM(W5:W35) -> 0 | X36: =SUM(X5:X35) -> 0 | Y36: =SUM(Y5:Y35) -> 0 | AA36: Toplam | AB36: =SUM(AB5:AB35) -> 0 | AC36: =SUM(AC5:AC35) -> 0 | AD36: =SUM(AD5:AD35) -> 0 | AF36: Toplam | AG36: =SUM(AG5:AG35) -> 0 | AH36: =SUM(AH5:AH35) -> 0 | AI36: =SUM(AI5:AI35) -> 0 | AK36: Toplam | AL36: =SUM(AL5:AL35) -> 0 | AM36: =SUM(AM5:AM35) -> 0 | AN36: =SUM(AN5:AN35) -> 0 | AP36: Toplam | AQ36: =SUM(AQ5:AQ35) -> 0 | AR36: =SUM(AR5:AR35) -> 0 | AS36: =SUM(AS5:AS35) -> 0 | AU36: Toplam | AV36: =SUM(AV5:AV35) -> 0 | AW36: =SUM(AW5:AW35) -> 0 | AX36: =SUM(AX5:AX35) -> 0 | AZ36: Toplam | BA36: =SUM(BA5:BA35) -> 0 | BB36: =SUM(BB5:BB35) -> 0 | BC36: =SUM(BC5:BC35) -> 0 | BE36: Toplam | BF36: =SUM(BF5:BF35) -> 0 | BG36: =SUM(BG5:BG35) -> 0 | BH36: =SUM(BH5:BH35) -> 0 | BJ36: Toplam | BK36: =SUM(BK5:BK35) -> 0 | BL36: =SUM(BL5:BL35) -> 0 | BM36: =SUM(BM5:BM35) -> 0
BR39: Toplam | BT39: =SUM(BT5:BT36) -> 0 | BU39: =SUM(BU5:BU36) -> 0 | BV39: =SUM(BV5:BV36) -> 0

Sheet No.3
B2: Ürün Kodu: | D2: ='SİPARİŞ FORMU'!B10 -> 3 | G2: ÜRETİM VERİLERİ | BR2: SEVK VERİLERİ
B3: Sipariş No: | D3: ='SİPARİŞ FORMU'!C4 -> 0 | BR3: Tarih | BS3: Sevk yeri | BT3: Sevk Metre | BU3: Sevk Ad/Kg | BV3: Sevk Top Sayısı | BW3: Çeki Listesi | BX3: Açıklama
B4: Müşteri: | D4: ='SİPARİŞ FORMU'!C5 -> 0 | G4: Tarih | H4: Metre | I4: Kg/Ad | J4: Top Sayısı | L4: Tarih | M4: Metre | N4: Kg/Ad | O4: Top Sayısı | Q4: Tarih | R4: Metre | S4: Kg/Ad | T4: Top Sayısı | V4: Tarih | W4: Metre | X4: Kg/Ad | Y4: Top Sayısı | AA4: Tarih | AB4: Metre | AC4: Kg/Ad | AD4: Top Sayısı | AF4: Tarih | AG4: Metre | AH4: Kg/Ad | AI4: Top Sayısı | AK4: Tarih | AL4: Metre | AM4: Kg/Ad | AN4: Top Sayısı | AP4: Tarih | AQ4: Metre | AR4: Kg/Ad | AS4: Top Sayısı | AU4: Tarih | AV4: Metre | AW4: Kg/Ad | AX4: Top Sayısı | AZ4: Tarih | BA4: Metre | BB4: Kg/Ad | BC4: Top Sayısı | BE4: Tarih | BF4: Metre | BG4: Kg/Ad | BH4: Top Sayısı | BJ4: Tarih | BK4: Metre | BL4: Kg/Ad | BM4: Top Sayısı
B5: Ürün Adı: | D5: ='SİPARİŞ FORMU'!C10 -> 0
B6: Renk: | D6: ='SİPARİŞ FORMU'!G10 -> 0
B7: Kumaş Eni: | D7: ='SİPARİŞ FORMU'!H10 -> 0
B8: Sipariş Mt/Ad: | D8: ='SİPARİŞ FORMU'!I10 -> 0
B9: Üretilen Metre | D9: =+H36+M36+R36+W36+AB36+AG36+AL36+AQ36+AV36+BA36+BF36+BK36 -> 0
B10: Üretilen Kg/Ad | D10: =+I36+N36+S36+X36+AC36+AH36+AM36+AR36+AW36+BB36+BG36+BL36 -> 0
B11: Üretilen Top Sayısı | D11: =+J36+O36+T36+Y36+AD36+AI36+AN36+AS36+AX36+BC36+BH36+BM36 -> 0
B12: Sevk Metre | D12: =BT39 -> 0
B13: Sevk Kg/Ad | D13: =BU39 -> 0
B14: Sevk Top Sayısı | D14: =BV39 -> 0
B15: Stok Metre | D15: =D9-D12 -> 0
B16: Stok Kg/Ad | D16: =D10-D13 -> 0
B17: Stok Top Sayısı | D17: =D11-D14 -> 0
B19: Üretim Durumu | D19: =D9/D8 -> #DIV/0!
G36: Toplam | H36: =SUM(H5:H35) -> 0 | I36: =SUM(I5:I35) -> 0 | J36: =SUM(J5:J35) -> 0 | L36: Toplam | M36: =SUM(M5:M35) -> 0 | N36: =SUM(N5:N35) -> 0 | O36: =SUM(O5:O35) -> 0 | Q36: Toplam | R36: =SUM(R5:R35) -> 0 | S36: =SUM(S5:S35) -> 0 | T36: =SUM(T5:T35) -> 0 | V36: Toplam | W36: =SUM(W5:W35) -> 0 | X36: =SUM(X5:X35) -> 0 | Y36: =SUM(Y5:Y35) -> 0 | AA36: Toplam | AB36: =SUM(AB5:AB35) -> 0 | AC36: =SUM(AC5:AC35) -> 0 | AD36: =SUM(AD5:AD35) -> 0 | AF36: Toplam | AG36: =SUM(AG5:AG35) -> 0 | AH36: =SUM(AH5:AH35) -> 0 | AI36: =SUM(AI5:AI35) -> 0 | AK36: Toplam | AL36: =SUM(AL5:AL35) -> 0 | AM36: =SUM(AM5:AM35) -> 0 | AN36: =SUM(AN5:AN35) -> 0 | AP36: Toplam | AQ36: =SUM(AQ5:AQ35) -> 0 | AR36: =SUM(AR5:AR35) -> 0 | AS36: =SUM(AS5:AS35) -> 0 | AU36: Toplam | AV36: =SUM(AV5:AV35) -> 0 | AW36: =SUM(AW5:AW35) -> 0 | AX36: =SUM(AX5:AX35) -> 0 | AZ36: Toplam | BA36: =SUM(BA5:BA35) -> 0 | BB36: =SUM(BB5:BB35) -> 0 | BC36: =SUM(BC5:BC35) -> 0 | BE36: Toplam | BF36: =SUM(BF5:BF35) -> 0 | BG36: =SUM(BG5:BG35) -> 0 | BH36: =SUM(BH5:BH35) -> 0 | BJ36: Toplam | BK36: =SUM(BK5:BK35) -> 0 | BL36: =SUM(BL5:BL35) -> 0 | BM36: =SUM(BM5:BM35) -> 0
BR39: Toplam | BT39: =SUM(BT5:BT36) -> 0 | BU39: =SUM(BU5:BU36) -> 0 | BV39: =SUM(BV5:BV36) -> 0

Sheet No.4
B2: Ürün Kodu: | D2: ='SİPARİŞ FORMU'!B11 -> 4 | G2: ÜRETİM VERİLERİ | BR2: SEVK VERİLERİ
B3: Sipariş No: | D3: ='SİPARİŞ FORMU'!C4 -> 0 | BR3: Tarih | BS3: Sevk yeri | BT3: Sevk Metre | BU3: Sevk Ad/Kg | BV3: Sevk Top Sayısı | BW3: Çeki Listesi | BX3: Açıklama
B4: Müşteri: | D4: ='SİPARİŞ FORMU'!C5 -> 0 | G4: Tarih | H4: Metre | I4: Kg/Ad | J4: Top Sayısı | L4: Tarih | M4: Metre | N4: Kg/Ad | O4: Top Sayısı | Q4: Tarih | R4: Metre | S4: Kg/Ad | T4: Top Sayısı | V4: Tarih | W4: Metre | X4: Kg/Ad | Y4: Top Sayısı | AA4: Tarih | AB4: Metre | AC4: Kg/Ad | AD4: Top Sayısı | AF4: Tarih | AG4: Metre | AH4: Kg/Ad | AI4: Top Sayısı | AK4: Tarih | AL4: Metre | AM4: Kg/Ad | AN4: Top Sayısı | AP4: Tarih | AQ4: Metre | AR4: Kg/Ad | AS4: Top Sayısı | AU4: Tarih | AV4: Metre | AW4: Kg/Ad | AX4: Top Sayısı | AZ4: Tarih | BA4: Metre | BB4: Kg/Ad | BC4: Top Sayısı | BE4: Tarih | BF4: Metre | BG4: Kg/Ad | BH4: Top Sayısı | BJ4: Tarih | BK4: Metre | BL4: Kg/Ad | BM4: Top Sayısı
B5: Ürün Adı: | D5: ='SİPARİŞ FORMU'!C11 -> 0
B6: Renk: | D6: ='SİPARİŞ FORMU'!G11 -> 0
B7: Kumaş Eni: | D7: ='SİPARİŞ FORMU'!H11 -> 0
B8: Sipariş Mt/Ad: | D8: ='SİPARİŞ FORMU'!I11 -> 0
B9: Üretilen Metre | D9: =+H36+M36+R36+W36+AB36+AG36+AL36+AQ36+AV36+BA36+BF36+BK36 -> 0
B10: Üretilen Kg/Ad | D10: =+I36+N36+S36+X36+AC36+AH36+AM36+AR36+AW36+BB36+BG36+BL36 -> 0
B11: Üretilen Top Sayısı | D11: =+J36+O36+T36+Y36+AD36+AI36+AN36+AS36+AX36+BC36+BH36+BM36 -> 0
B12: Sevk Metre | D12: =BT39 -> 0
B13: Sevk Kg/Ad | D13: =BU39 -> 0
B14: Sevk Top Sayısı | D14: =BV39 -> 0
B15: Stok Metre | D15: =D9-D12 -> 0
B16: Stok Kg/Ad | D16: =D10-D13 -> 0
B17: Stok Top Sayısı | D17: =D11-D14 -> 0
B19: Üretim Durumu | D19: =D9/D8 -> #DIV/0!
G36: Toplam | H36: =SUM(H5:H35) -> 0 | I36: =SUM(I5:I35) -> 0 | J36: =SUM(J5:J35) -> 0 | L36: Toplam | M36: =SUM(M5:M35) -> 0 | N36: =SUM(N5:N35) -> 0 | O36: =SUM(O5:O35) -> 0 | Q36: Toplam | R36: =SUM(R5:R35) -> 0 | S36: =SUM(S5:S35) -> 0 | T36: =SUM(T5:T35) -> 0 | V36: Toplam | W36: =SUM(W5:W35) -> 0 | X36: =SUM(X5:X35) -> 0 | Y36: =SUM(Y5:Y35) -> 0 | AA36: Toplam | AB36: =SUM(AB5:AB35) -> 0 | AC36: =SUM(AC5:AC35) -> 0 | AD36: =SUM(AD5:AD35) -> 0 | AF36: Toplam | AG36: =SUM(AG5:AG35) -> 0 | AH36: =SUM(AH5:AH35) -> 0 | AI36: =SUM(AI5:AI35) -> 0 | AK36: Toplam | AL36: =SUM(AL5:AL35) -> 0 | AM36: =SUM(AM5:AM35) -> 0 | AN36: =SUM(AN5:AN35) -> 0 | AP36: Toplam | AQ36: =SUM(AQ5:AQ35) -> 0 | AR36: =SUM(AR5:AR35) -> 0 | AS36: =SUM(AS5:AS35) -> 0 | AU36: Toplam | AV36: =SUM(AV5:AV35) -> 0 | AW36: =SUM(AW5:AW35) -> 0 | AX36: =SUM(AX5:AX35) -> 0 | AZ36: Toplam | BA36: =SUM(BA5:BA35) -> 0 | BB36: =SUM(BB5:BB35) -> 0 | BC36: =SUM(BC5:BC35) -> 0 | BE36: Toplam | BF36: =SUM(BF5:BF35) -> 0 | BG36: =SUM(BG5:BG35) -> 0 | BH36: =SUM(BH5:BH35) -> 0 | BJ36: Toplam | BK36: =SUM(BK5:BK35) -> 0 | BL36: =SUM(BL5:BL35) -> 0 | BM36: =SUM(BM5:BM35) -> 0
BR39: Toplam | BT39: =SUM(BT5:BT36) -> 0 | BU39: =SUM(BU5:BU36) -> 0 | BV39: =SUM(BV5:BV36) -> 0

Sheet No.5
B2: Ürün Kodu: | D2: ='SİPARİŞ FORMU'!B12 -> 5 | G2: ÜRETİM VERİLERİ | BR2: SEVK VERİLERİ
B3: Sipariş No: | D3: ='SİPARİŞ FORMU'!C4 -> 0 | BR3: Tarih | BS3: Sevk yeri | BT3: Sevk Metre | BU3: Sevk Ad/Kg | BV3: Sevk Top Sayısı | BW3: Çeki Listesi | BX3: Açıklama
B4: Müşteri: | D4: ='SİPARİŞ FORMU'!C5 -> 0 | G4: Tarih | H4: Metre | I4: Kg/Ad | J4: Top Sayısı | L4: Tarih | M4: Metre | N4: Kg/Ad | O4: Top Sayısı | Q4: Tarih | R4: Metre | S4: Kg/Ad | T4: Top Sayısı | V4: Tarih | W4: Metre | X4: Kg/Ad | Y4: Top Sayısı | AA4: Tarih | AB4: Metre | AC4: Kg/Ad | AD4: Top Sayısı | AF4: Tarih | AG4: Metre | AH4: Kg/Ad | AI4: Top Sayısı | AK4: Tarih | AL4: Metre | AM4: Kg/Ad | AN4: Top Sayısı | AP4: Tarih | AQ4: Metre | AR4: Kg/Ad | AS4: Top Sayısı | AU4: Tarih | AV4: Metre | AW4: Kg/Ad | AX4: Top Sayısı | AZ4: Tarih | BA4: Metre | BB4: Kg/Ad | BC4: Top Sayısı | BE4: Tarih | BF4: Metre | BG4: Kg/Ad | BH4: Top Sayısı | BJ4: Tarih | BK4: Metre | BL4: Kg/Ad | BM4: Top Sayısı
B5: Ürün Adı: | D5: ='SİPARİŞ FORMU'!C12 -> 0
B6: Renk: | D6: ='SİPARİŞ FORMU'!G12 -> 0
B7: Kumaş Eni: | D7: ='SİPARİŞ FORMU'!H12 -> 0
B8: Sipariş Mt/Ad: | D8: ='SİPARİŞ FORMU'!I12 -> 0
B9: Üretilen Metre | D9: =+H36+M36+R36+W36+AB36+AG36+AL36+AQ36+AV36+BA36+BF36+BK36 -> 0
B10: Üretilen Kg/Ad | D10: =+I36+N36+S36+X36+AC36+AH36+AM36+AR36+AW36+BB36+BG36+BL36 -> 0
B11: Üretilen Top Sayısı | D11: =+J36+O36+T36+Y36+AD36+AI36+AN36+AS36+AX36+BC36+BH36+BM36 -> 0
B12: Sevk Metre | D12: =BT39 -> 0
B13: Sevk Kg/Ad | D13: =BU39 -> 0
B14: Sevk Top Sayısı | D14: =BV39 -> 0
B15: Stok Metre | D15: =D9-D12 -> 0
B16: Stok Kg/Ad | D16: =D10-D13 -> 0
B17: Stok Top Sayısı | D17: =D11-D14 -> 0
B19: Üretim Durumu | D19: =D9/D8 -> #DIV/0!
G36: Toplam | H36: =SUM(H5:H35) -> 0 | I36: =SUM(I5:I35) -> 0 | J36: =SUM(J5:J35) -> 0 | L36: Toplam | M36: =SUM(M5:M35) -> 0 | N36: =SUM(N5:N35) -> 0 | O36: =SUM(O5:O35) -> 0 | Q36: Toplam | R36: =SUM(R5:R35) -> 0 | S36: =SUM(S5:S35) -> 0 | T36: =SUM(T5:T35) -> 0 | V36: Toplam | W36: =SUM(W5:W35) -> 0 | X36: =SUM(X5:X35) -> 0 | Y36: =SUM(Y5:Y35) -> 0 | AA36: Toplam | AB36: =SUM(AB5:AB35) -> 0 | AC36: =SUM(AC5:AC35) -> 0 | AD36: =SUM(AD5:AD35) -> 0 | AF36: Toplam | AG36: =SUM(AG5:AG35) -> 0 | AH36: =SUM(AH5:AH35) -> 0 | AI36: =SUM(AI5:AI35) -> 0 | AK36: Toplam | AL36: =SUM(AL5:AL35) -> 0 | AM36: =SUM(AM5:AM35) -> 0 | AN36: =SUM(AN5:AN35) -> 0 | AP36: Toplam | AQ36: =SUM(AQ5:AQ35) -> 0 | AR36: =SUM(AR5:AR35) -> 0 | AS36: =SUM(AS5:AS35) -> 0 | AU36: Toplam | AV36: =SUM(AV5:AV35) -> 0 | AW36: =SUM(AW5:AW35) -> 0 | AX36: =SUM(AX5:AX35) -> 0 | AZ36: Toplam | BA36: =SUM(BA5:BA35) -> 0 | BB36: =SUM(BB5:BB35) -> 0 | BC36: =SUM(BC5:BC35) -> 0 | BE36: Toplam | BF36: =SUM(BF5:BF35) -> 0 | BG36: =SUM(BG5:BG35) -> 0 | BH36: =SUM(BH5:BH35) -> 0 | BJ36: Toplam | BK36: =SUM(BK5:BK35) -> 0 | BL36: =SUM(BL5:BL35) -> 0 | BM36: =SUM(BM5:BM35) -> 0
BR39: Toplam | BT39: =SUM(BT5:BT36) -> 0 | BU39: =SUM(BU5:BU36) -> 0 | BV39: =SUM(BV5:BV36) -> 0

Sheet No.6
B2: Ürün Kodu: | D2: ='SİPARİŞ FORMU'!B13 -> 6 | G2: ÜRETİM VERİLERİ | BR2: SEVK VERİLERİ
B3: Sipariş No: | D3: ='SİPARİŞ FORMU'!C4 -> 0 | BR3: Tarih | BS3: Sevk yeri | BT3: Sevk Metre | BU3: Sevk Ad/Kg | BV3: Sevk Top Sayısı | BW3: Çeki Listesi | BX3: Açıklama
B4: Müşteri: | D4: ='SİPARİŞ FORMU'!C5 -> 0 | G4: Tarih | H4: Metre | I4: Kg/Ad | J4: Top Sayısı | L4: Tarih | M4: Metre | N4: Kg/Ad | O4: Top Sayısı | Q4: Tarih | R4: Metre | S4: Kg/Ad | T4: Top Sayısı | V4: Tarih | W4: Metre | X4: Kg/Ad | Y4: Top Sayısı | AA4: Tarih | AB4: Metre | AC4: Kg/Ad | AD4: Top Sayısı | AF4: Tarih | AG4: Metre | AH4: Kg/Ad | AI4: Top Sayısı | AK4: Tarih | AL4: Metre | AM4: Kg/Ad | AN4: Top Sayısı | AP4: Tarih | AQ4: Metre | AR4: Kg/Ad | AS4: Top Sayısı | AU4: Tarih | AV4: Metre | AW4: Kg/Ad | AX4: Top Sayısı | AZ4: Tarih | BA4: Metre | BB4: Kg/Ad | BC4: Top Sayısı | BE4: Tarih | BF4: Metre | BG4: Kg/Ad | BH4: Top Sayısı | BJ4: Tarih | BK4: Metre | BL4: Kg/Ad | BM4: Top Sayısı
B5: Ürün Adı: | D5: ='SİPARİŞ FORMU'!C13 -> 0
B6: Renk: | D6: ='SİPARİŞ FORMU'!G13 -> 0
B7: Kumaş Eni: | D7: ='SİPARİŞ FORMU'!H13 -> 0
B8: Sipariş Mt/Ad: | D8: ='SİPARİŞ FORMU'!I13 -> 0
B9: Üretilen Metre | D9: =+H36+M36+R36+W36+AB36+AG36+AL36+AQ36+AV36+BA36+BF36+BK36 -> 0
B10: Üretilen Kg/Ad | D10: =+I36+N36+S36+X36+AC36+AH36+AM36+AR36+AW36+BB36+BG36+BL36 -> 0
B11: Üretilen Top Sayısı | D11: =+J36+O36+T36+Y36+AD36+AI36+AN36+AS36+AX36+BC36+BH36+BM36 -> 0
B12: Sevk Metre | D12: =BT39 -> 0
B13: Sevk Kg/Ad | D13: =BU39 -> 0
B14: Sevk Top Sayısı | D14: =BV39 -> 0
B15: Stok Metre | D15: =D9-D12 -> 0
B16: Stok Kg/Ad | D16: =D10-D13 -> 0
B17: Stok Top Sayısı | D17: =D11-D14 -> 0
B19: Üretim Durumu | D19: =D9/D8 -> #DIV/0!
G36: Toplam | H36: =SUM(H5:H35) -> 0 | I36: =SUM(I5:I35) -> 0 | J36: =SUM(J5:J35) -> 0 | L36: Toplam | M36: =SUM(M5:M35) -> 0 | N36: =SUM(N5:N35) -> 0 | O36: =SUM(O5:O35) -> 0 | Q36: Toplam | R36: =SUM(R5:R35) -> 0 | S36: =SUM(S5:S35) -> 0 | T36: =SUM(T5:T35) -> 0 | V36: Toplam | W36: =SUM(W5:W35) -> 0 | X36: =SUM(X5:X35) -> 0 | Y36: =SUM(Y5:Y35) -> 0 | AA36: Toplam | AB36: =SUM(AB5:AB35) -> 0 | AC36: =SUM(AC5:AC35) -> 0 | AD36: =SUM(AD5:AD35) -> 0 | AF36: Toplam | AG36: =SUM(AG5:AG35) -> 0 | AH36: =SUM(AH5:AH35) -> 0 | AI36: =SUM(AI5:AI35) -> 0 | AK36: Toplam | AL36: =SUM(AL5:AL35) -> 0 | AM36: =SUM(AM5:AM35) -> 0 | AN36: =SUM(AN5:AN35) -> 0 | AP36: Toplam | AQ36: =SUM(AQ5:AQ35) -> 0 | AR36: =SUM(AR5:AR35) -> 0 | AS36: =SUM(AS5:AS35) -> 0 | AU36: Toplam | AV36: =SUM(AV5:AV35) -> 0 | AW36: =SUM(AW5:AW35) -> 0 | AX36: =SUM(AX5:AX35) -> 0 | AZ36: Toplam | BA36: =SUM(BA5:BA35) -> 0 | BB36: =SUM(BB5:BB35) -> 0 | BC36: =SUM(BC5:BC35) -> 0 | BE36: Toplam | BF36: =SUM(BF5:BF35) -> 0 | BG36: =SUM(BG5:BG35) -> 0 | BH36: =SUM(BH5:BH35) -> 0 | BJ36: Toplam | BK36: =SUM(BK5:BK35) -> 0 | BL36: =SUM(BL5:BL35) -> 0 | BM36: =SUM(BM5:BM35) -> 0
BR39: Toplam | BT39: =SUM(BT5:BT36) -> 0 | BU39: =SUM(BU5:BU36) -> 0 | BV39: =SUM(BV5:BV36) -> 0

Sheet No.7
B2: Ürün Kodu: | D2: ='SİPARİŞ FORMU'!B14 -> 7 | G2: ÜRETİM VERİLERİ | BR2: SEVK VERİLERİ
B3: Sipariş No: | D3: ='SİPARİŞ FORMU'!C4 -> 0 | BR3: Tarih | BS3: Sevk yeri | BT3: Sevk Metre | BU3: Sevk Ad/Kg | BV3: Sevk Top Sayısı | BW3: Çeki Listesi | BX3: Açıklama
B4: Müşteri: | D4: ='SİPARİŞ FORMU'!C5 -> 0 | G4: Tarih | H4: Metre | I4: Kg/Ad | J4: Top Sayısı | L4: Tarih | M4: Metre | N4: Kg/Ad | O4: Top Sayısı | Q4: Tarih | R4: Metre | S4: Kg/Ad | T4: Top Sayısı | V4: Tarih | W4: Metre | X4: Kg/Ad | Y4: Top Sayısı | AA4: Tarih | AB4: Metre | AC4: Kg/Ad | AD4: Top Sayısı | AF4: Tarih | AG4: Metre | AH4: Kg/Ad | AI4: Top Sayısı | AK4: Tarih | AL4: Metre | AM4: Kg/Ad | AN4: Top Sayısı | AP4: Tarih | AQ4: Metre | AR4: Kg/Ad | AS4: Top Sayısı | AU4: Tarih | AV4: Metre | AW4: Kg/Ad | AX4: Top Sayısı | AZ4: Tarih | BA4: Metre | BB4: Kg/Ad | BC4: Top Sayısı | BE4: Tarih | BF4: Metre | BG4: Kg/Ad | BH4: Top Sayısı | BJ4: Tarih | BK4: Metre | BL4: Kg/Ad | BM4: Top Sayısı
B5: Ürün Adı: | D5: ='SİPARİŞ FORMU'!C14 -> 0
B6: Renk: | D6: ='SİPARİŞ FORMU'!G14 -> 0
B7: Kumaş Eni: | D7: ='SİPARİŞ FORMU'!H14 -> 0
B8: Sipariş Mt/Ad: | D8: ='SİPARİŞ FORMU'!I14 -> 0
B9: Üretilen Metre | D9: =+H36+M36+R36+W36+AB36+AG36+AL36+AQ36+AV36+BA36+BF36+BK36 -> 0
B10: Üretilen Kg/Ad | D10: =+I36+N36+S36+X36+AC36+AH36+AM36+AR36+AW36+BB36+BG36+BL36 -> 0
B11: Üretilen Top Sayısı | D11: =+J36+O36+T36+Y36+AD36+AI36+AN36+AS36+AX36+BC36+BH36+BM36 -> 0
B12: Sevk Metre | D12: =BT39 -> 0
B13: Sevk Kg/Ad | D13: =BU39 -> 0
B14: Sevk Top Sayısı | D14: =BV39 -> 0
B15: Stok Metre | D15: =D9-D12 -> 0
B16: Stok Kg/Ad | D16: =D10-D13 -> 0
B17: Stok Top Sayısı | D17: =D11-D14 -> 0
B19: Üretim Durumu | D19: =D9/D8 -> #DIV/0!
G36: Toplam | H36: =SUM(H5:H35) -> 0 | I36: =SUM(I5:I35) -> 0 | J36: =SUM(J5:J35) -> 0 | L36: Toplam | M36: =SUM(M5:M35) -> 0 | N36: =SUM(N5:N35) -> 0 | O36: =SUM(O5:O35) -> 0 | Q36: Toplam | R36: =SUM(R5:R35) -> 0 | S36: =SUM(S5:S35) -> 0 | T36: =SUM(T5:T35) -> 0 | V36: Toplam | W36: =SUM(W5:W35) -> 0 | X36: =SUM(X5:X35) -> 0 | Y36: =SUM(Y5:Y35) -> 0 | AA36: Toplam | AB36: =SUM(AB5:AB35) -> 0 | AC36: =SUM(AC5:AC35) -> 0 | AD36: =SUM(AD5:AD35) -> 0 | AF36: Toplam | AG36: =SUM(AG5:AG35) -> 0 | AH36: =SUM(AH5:AH35) -> 0 | AI36: =SUM(AI5:AI35) -> 0 | AK36: Toplam | AL36: =SUM(AL5:AL35) -> 0 | AM36: =SUM(AM5:AM35) -> 0 | AN36: =SUM(AN5:AN35) -> 0 | AP36: Toplam | AQ36: =SUM(AQ5:AQ35) -> 0 | AR36: =SUM(AR5:AR35) -> 0 | AS36: =SUM(AS5:AS35) -> 0 | AU36: Toplam | AV36: =SUM(AV5:AV35) -> 0 | AW36: =SUM(AW5:AW35) -> 0 | AX36: =SUM(AX5:AX35) -> 0 | AZ36: Toplam | BA36: =SUM(BA5:BA35) -> 0 | BB36: =SUM(BB5:BB35) -> 0 | BC36: =SUM(BC5:BC35) -> 0 | BE36: Toplam | BF36: =SUM(BF5:BF35) -> 0 | BG36: =SUM(BG5:BG35) -> 0 | BH36: =SUM(BH5:BH35) -> 0 | BJ36: Toplam | BK36: =SUM(BK5:BK35) -> 0 | BL36: =SUM(BL5:BL35) -> 0 | BM36: =SUM(BM5:BM35) -> 0
BR39: Toplam | BT39: =SUM(BT5:BT36) -> 0 | BU39: =SUM(BU5:BU36) -> 0 | BV39: =SUM(BV5:BV36) -> 0

Sheet No.8
B2: Ürün Kodu: | D2: ='SİPARİŞ FORMU'!B15 -> 8 | G2: ÜRETİM VERİLERİ | BR2: SEVK VERİLERİ
B3: Sipariş No: | D3: ='SİPARİŞ FORMU'!C4 -> 0 | BR3: Tarih | BS3: Sevk yeri | BT3: Sevk Metre | BU3: Sevk Ad/Kg | BV3: Sevk Top Sayısı | BW3: Çeki Listesi | BX3: Açıklama
B4: Müşteri: | D4: ='SİPARİŞ FORMU'!C5 -> 0 | G4: Tarih | H4: Metre | I4: Kg/Ad | J4: Top Sayısı | L4: Tarih | M4: Metre | N4: Kg/Ad | O4: Top Sayısı | Q4: Tarih | R4: Metre | S4: Kg/Ad | T4: Top Sayısı | V4: Tarih | W4: Metre | X4: Kg/Ad | Y4: Top Sayısı | AA4: Tarih | AB4: Metre | AC4: Kg/Ad | AD4: Top Sayısı | AF4: Tarih | AG4: Metre | AH4: Kg/Ad | AI4: Top Sayısı | AK4: Tarih | AL4: Metre | AM4: Kg/Ad | AN4: Top Sayısı | AP4: Tarih | AQ4: Metre | AR4: Kg/Ad | AS4: Top Sayısı | AU4: Tarih | AV4: Metre | AW4: Kg/Ad | AX4: Top Sayısı | AZ4: Tarih | BA4: Metre | BB4: Kg/Ad | BC4: Top Sayısı | BE4: Tarih | BF4: Metre | BG4: Kg/Ad | BH4: Top Sayısı | BJ4: Tarih | BK4: Metre | BL4: Kg/Ad | BM4: Top Sayısı
B5: Ürün Adı: | D5: ='SİPARİŞ FORMU'!C15 -> 0
B6: Renk: | D6: ='SİPARİŞ FORMU'!G15 -> 0
B7: Kumaş Eni: | D7: ='SİPARİŞ FORMU'!H15 -> 0
B8: Sipariş Mt/Ad: | D8: ='SİPARİŞ FORMU'!I15 -> 0
B9: Üretilen Metre | D9: =+H36+M36+R36+W36+AB36+AG36+AL36+AQ36+AV36+BA36+BF36+BK36 -> 0
B10: Üretilen Kg/Ad | D10: =+I36+N36+S36+X36+AC36+AH36+AM36+AR36+AW36+BB36+BG36+BL36 -> 0
B11: Üretilen Top Sayısı | D11: =+J36+O36+T36+Y36+AD36+AI36+AN36+AS36+AX36+BC36+BH36+BM36 -> 0
B12: Sevk Metre | D12: =BT39 -> 0
B13: Sevk Kg/Ad | D13: =BU39 -> 0
B14: Sevk Top Sayısı | D14: =BV39 -> 0
B15: Stok Metre | D15: =D9-D12 -> 0
B16: Stok Kg/Ad | D16: =D10-D13 -> 0
B17: Stok Top Sayısı | D17: =D11-D14 -> 0
B19: Üretim Durumu | D19: =D9/D8 -> #DIV/0!
G36: Toplam | H36: =SUM(H5:H35) -> 0 | I36: =SUM(I5:I35) -> 0 | J36: =SUM(J5:J35) -> 0 | L36: Toplam | M36: =SUM(M5:M35) -> 0 | N36: =SUM(N5:N35) -> 0 | O36: =SUM(O5:O35) -> 0 | Q36: Toplam | R36: =SUM(R5:R35) -> 0 | S36: =SUM(S5:S35) -> 0 | T36: =SUM(T5:T35) -> 0 | V36: Toplam | W36: =SUM(W5:W35) -> 0 | X36: =SUM(X5:X35) -> 0 | Y36: =SUM(Y5:Y35) -> 0 | AA36: Toplam | AB36: =SUM(AB5:AB35) -> 0 | AC36: =SUM(AC5:AC35) -> 0 | AD36: =SUM(AD5:AD35) -> 0 | AF36: Toplam | AG36: =SUM(AG5:AG35) -> 0 | AH36: =SUM(AH5:AH35) -> 0 | AI36: =SUM(AI5:AI35) -> 0 | AK36: Toplam | AL36: =SUM(AL5:AL35) -> 0 | AM36: =SUM(AM5:AM35) -> 0 | AN36: =SUM(AN5:AN35) -> 0 | AP36: Toplam | AQ36: =SUM(AQ5:AQ35) -> 0 | AR36: =SUM(AR5:AR35) -> 0 | AS36: =SUM(AS5:AS35) -> 0 | AU36: Toplam | AV36: =SUM(AV5:AV35) -> 0 | AW36: =SUM(AW5:AW35) -> 0 | AX36: =SUM(AX5:AX35) -> 0 | AZ36: Toplam | BA36: =SUM(BA5:BA35) -> 0 | BB36: =SUM(BB5:BB35) -> 0 | BC36: =SUM(BC5:BC35) -> 0 | BE36: Toplam | BF36: =SUM(BF5:BF35) -> 0 | BG36: =SUM(BG5:BG35) -> 0 | BH36: =SUM(BH5:BH35) -> 0 | BJ36: Toplam | BK36: =SUM(BK5:BK35) -> 0 | BL36: =SUM(BL5:BL35) -> 0 | BM36: =SUM(BM5:BM35) -> 0
BR39: Toplam | BT39: =SUM(BT5:BT36) -> 0 | BU39: =SUM(BU5:BU36) -> 0 | BV39: =SUM(BV5:BV36) -> 0

Sheet No.9
B2: Ürün Kodu: | D2: ='SİPARİŞ FORMU'!B16 -> 9 | G2: ÜRETİM VERİLERİ | BR2: SEVK VERİLERİ
B3: Sipariş No: | D3: ='SİPARİŞ FORMU'!C4 -> 0 | BR3: Tarih | BS3: Sevk yeri | BT3: Sevk Metre | BU3: Sevk Ad/Kg | BV3: Sevk Top Sayısı | BW3: Çeki Listesi | BX3: Açıklama
B4: Müşteri: | D4: ='SİPARİŞ FORMU'!C5 -> 0 | G4: Tarih | H4: Metre | I4: Kg/Ad | J4: Top Sayısı | L4: Tarih | M4: Metre | N4: Kg/Ad | O4: Top Sayısı | Q4: Tarih | R4: Metre | S4: Kg/Ad | T4: Top Sayısı | V4: Tarih | W4: Metre | X4: Kg/Ad | Y4: Top Sayısı | AA4: Tarih | AB4: Metre | AC4: Kg/Ad | AD4: Top Sayısı | AF4: Tarih | AG4: Metre | AH4: Kg/Ad | AI4: Top Sayısı | AK4: Tarih | AL4: Metre | AM4: Kg/Ad | AN4: Top Sayısı | AP4: Tarih | AQ4: Metre | AR4: Kg/Ad | AS4: Top Sayısı | AU4: Tarih | AV4: Metre | AW4: Kg/Ad | AX4: Top Sayısı | AZ4: Tarih | BA4: Metre | BB4: Kg/Ad | BC4: Top Sayısı | BE4: Tarih | BF4: Metre | BG4: Kg/Ad | BH4: Top Sayısı | BJ4: Tarih | BK4: Metre | BL4: Kg/Ad | BM4: Top Sayısı
B5: Ürün Adı: | D5: ='SİPARİŞ FORMU'!C16 -> 0
B6: Renk: | D6: ='SİPARİŞ FORMU'!G16 -> 0
B7: Kumaş Eni: | D7: ='SİPARİŞ FORMU'!H16 -> 0
B8: Sipariş Mt/Ad: | D8: ='SİPARİŞ FORMU'!I16 -> 0
B9: Üretilen Metre | D9: =+H36+M36+R36+W36+AB36+AG36+AL36+AQ36+AV36+BA36+BF36+BK36 -> 0
B10: Üretilen Kg/Ad | D10: =+I36+N36+S36+X36+AC36+AH36+AM36+AR36+AW36+BB36+BG36+BL36 -> 0
B11: Üretilen Top Sayısı | D11: =+J36+O36+T36+Y36+AD36+AI36+AN36+AS36+AX36+BC36+BH36+BM36 -> 0
B12: Sevk Metre | D12: =BT39 -> 0
B13: Sevk Kg/Ad | D13: =BU39 -> 0
B14: Sevk Top Sayısı | D14: =BV39 -> 0
B15: Stok Metre | D15: =D9-D12 -> 0
B16: Stok Kg/Ad | D16: =D10-D13 -> 0
B17: Stok Top Sayısı | D17: =D11-D14 -> 0
B19: Üretim Durumu | D19: =D9/D8 -> #DIV/0!
G36: Toplam | H36: =SUM(H5:H35) -> 0 | I36: =SUM(I5:I35) -> 0 | J36: =SUM(J5:J35) -> 0 | L36: Toplam | M36: =SUM(M5:M35) -> 0 | N36: =SUM(N5:N35) -> 0 | O36: =SUM(O5:O35) -> 0 | Q36: Toplam | R36: =SUM(R5:R35) -> 0 | S36: =SUM(S5:S35) -> 0 | T36: =SUM(T5:T35) -> 0 | V36: Toplam | W36: =SUM(W5:W35) -> 0 | X36: =SUM(X5:X35) -> 0 | Y36: =SUM(Y5:Y35) -> 0 | AA36: Toplam | AB36: =SUM(AB5:AB35) -> 0 | AC36: =SUM(AC5:AC35) -> 0 | AD36: =SUM(AD5:AD35) -> 0 | AF36: Toplam | AG36: =SUM(AG5:AG35) -> 0 | AH36: =SUM(AH5:AH35) -> 0 | AI36: =SUM(AI5:AI35) -> 0 | AK36: Toplam | AL36: =SUM(AL5:AL35) -> 0 | AM36: =SUM(AM5:AM35) -> 0 | AN36: =SUM(AN5:AN35) -> 0 | AP36: Toplam | AQ36: =SUM(AQ5:AQ35) -> 0 | AR36: =SUM(AR5:AR35) -> 0 | AS36: =SUM(AS5:AS35) -> 0 | AU36: Toplam | AV36: =SUM(AV5:AV35) -> 0 | AW36: =SUM(AW5:AW35) -> 0 | AX36: =SUM(AX5:AX35) -> 0 | AZ36: Toplam | BA36: =SUM(BA5:BA35) -> 0 | BB36: =SUM(BB5:BB35) -> 0 | BC36: =SUM(BC5:BC35) -> 0 | BE36: Toplam | BF36: =SUM(BF5:BF35) -> 0 | BG36: =SUM(BG5:BG35) -> 0 | BH36: =SUM(BH5:BH35) -> 0 | BJ36: Toplam | BK36: =SUM(BK5:BK35) -> 0 | BL36: =SUM(BL5:BL35) -> 0 | BM36: =SUM(BM5:BM35) -> 0
BR39: Toplam | BT39: =SUM(BT5:BT36) -> 0 | BU39: =SUM(BU5:BU36) -> 0 | BV39: =SUM(BV5:BV36) -> 0

Sheet No.10
B2: Ürün Kodu: | D2: ='SİPARİŞ FORMU'!B17 -> 10 | G2: ÜRETİM VERİLERİ | BR2: SEVK VERİLERİ
B3: Sipariş No: | D3: ='SİPARİŞ FORMU'!C4 -> 0 | BR3: Tarih | BS3: Sevk yeri | BT3: Sevk Metre | BU3: Sevk Ad/Kg | BV3: Sevk Top Sayısı | BW3: Çeki Listesi | BX3: Açıklama
B4: Müşteri: | D4: ='SİPARİŞ FORMU'!C5 -> 0 | G4: Tarih | H4: Metre | I4: Kg/Ad | J4: Top Sayısı | L4: Tarih | M4: Metre | N4: Kg/Ad | O4: Top Sayısı | Q4: Tarih | R4: Metre | S4: Kg/Ad | T4: Top Sayısı | V4: Tarih | W4: Metre | X4: Kg/Ad | Y4: Top Sayısı | AA4: Tarih | AB4: Metre | AC4: Kg/Ad | AD4: Top Sayısı | AF4: Tarih | AG4: Metre | AH4: Kg/Ad | AI4: Top Sayısı | AK4: Tarih | AL4: Metre | AM4: Kg/Ad | AN4: Top Sayısı | AP4: Tarih | AQ4: Metre | AR4: Kg/Ad | AS4: Top Sayısı | AU4: Tarih | AV4: Metre | AW4: Kg/Ad | AX4: Top Sayısı | AZ4: Tarih | BA4: Metre | BB4: Kg/Ad | BC4: Top Sayısı | BE4: Tarih | BF4: Metre | BG4: Kg/Ad | BH4: Top Sayısı | BJ4: Tarih | BK4: Metre | BL4: Kg/Ad | BM4: Top Sayısı
B5: Ürün Adı: | D5: ='SİPARİŞ FORMU'!C17 -> 0
B6: Renk: | D6: ='SİPARİŞ FORMU'!G17 -> 0
B7: Kumaş Eni: | D7: ='SİPARİŞ FORMU'!H17 -> 0
B8: Sipariş Mt/Ad: | D8: ='SİPARİŞ FORMU'!I17 -> 0
B9: Üretilen Metre | D9: =+H36+M36+R36+W36+AB36+AG36+AL36+AQ36+AV36+BA36+BF36+BK36 -> 0
B10: Üretilen Kg/Ad | D10: =+I36+N36+S36+X36+AC36+AH36+AM36+AR36+AW36+BB36+BG36+BL36 -> 0
B11: Üretilen Top Sayısı | D11: =+J36+O36+T36+Y36+AD36+AI36+AN36+AS36+AX36+BC36+BH36+BM36 -> 0
B12: Sevk Metre | D12: =BT39 -> 0
B13: Sevk Kg/Ad | D13: =BU39 -> 0
B14: Sevk Top Sayısı | D14: =BV39 -> 0
B15: Stok Metre | D15: =D9-D12 -> 0
B16: Stok Kg/Ad | D16: =D10-D13 -> 0
B17: Stok Top Sayısı | D17: =D11-D14 -> 0
B19: Üretim Durumu | D19: =D9/D8 -> #DIV/0!
G36: Toplam | H36: =SUM(H5:H35) -> 0 | I36: =SUM(I5:I35) -> 0 | J36: =SUM(J5:J35) -> 0 | L36: Toplam | M36: =SUM(M5:M35) -> 0 | N36: =SUM(N5:N35) -> 0 | O36: =SUM(O5:O35) -> 0 | Q36: Toplam | R36: =SUM(R5:R35) -> 0 | S36: =SUM(S5:S35) -> 0 | T36: =SUM(T5:T35) -> 0 | V36: Toplam | W36: =SUM(W5:W35) -> 0 | X36: =SUM(X5:X35) -> 0 | Y36: =SUM(Y5:Y35) -> 0 | AA36: Toplam | AB36: =SUM(AB5:AB35) -> 0 | AC36: =SUM(AC5:AC35) -> 0 | AD36: =SUM(AD5:AD35) -> 0 | AF36: Toplam | AG36: =SUM(AG5:AG35) -> 0 | AH36: =SUM(AH5:AH35) -> 0 | AI36: =SUM(AI5:AI35) -> 0 | AK36: Toplam | AL36: =SUM(AL5:AL35) -> 0 | AM36: =SUM(AM5:AM35) -> 0 | AN36: =SUM(AN5:AN35) -> 0 | AP36: Toplam | AQ36: =SUM(AQ5:AQ35) -> 0 | AR36: =SUM(AR5:AR35) -> 0 | AS36: =SUM(AS5:AS35) -> 0 | AU36: Toplam | AV36: =SUM(AV5:AV35) -> 0 | AW36: =SUM(AW5:AW35) -> 0 | AX36: =SUM(AX5:AX35) -> 0 | AZ36: Toplam | BA36: =SUM(BA5:BA35) -> 0 | BB36: =SUM(BB5:BB35) -> 0 | BC36: =SUM(BC5:BC35) -> 0 | BE36: Toplam | BF36: =SUM(BF5:BF35) -> 0 | BG36: =SUM(BG5:BG35) -> 0 | BH36: =SUM(BH5:BH35) -> 0 | BJ36: Toplam | BK36: =SUM(BK5:BK35) -> 0 | BL36: =SUM(BL5:BL35) -> 0 | BM36: =SUM(BM5:BM35) -> 0
BR39: Toplam | BT39: =SUM(BT5:BT36) -> 0 | BU39: =SUM(BU5:BU36) -> 0 | BV39: =SUM(BV5:BV36) -> 0

Sheet No.11
B2: Ürün Kodu: | G2: ÜRETİM VERİLERİ | BR2: SEVK VERİLERİ
B3: Sipariş No: | D3: ='SİPARİŞ FORMU'!C4 -> 0 | BR3: Tarih | BS3: Sevk yeri | BT3: Sevk Metre | BU3: Sevk Ad/Kg | BV3: Sevk Top Sayısı | BW3: Çeki Listesi | BX3: Açıklama
B4: Müşteri: | D4: ='SİPARİŞ FORMU'!C5 -> 0 | G4: Tarih | H4: Metre | I4: Kg/Ad | J4: Top Sayısı | L4: Tarih | M4: Metre | N4: Kg/Ad | O4: Top Sayısı | Q4: Tarih | R4: Metre | S4: Kg/Ad | T4: Top Sayısı | V4: Tarih | W4: Metre | X4: Kg/Ad | Y4: Top Sayısı | AA4: Tarih | AB4: Metre | AC4: Kg/Ad | AD4: Top Sayısı | AF4: Tarih | AG4: Metre | AH4: Kg/Ad | AI4: Top Sayısı | AK4: Tarih | AL4: Metre | AM4: Kg/Ad | AN4: Top Sayısı | AP4: Tarih | AQ4: Metre | AR4: Kg/Ad | AS4: Top Sayısı | AU4: Tarih | AV4: Metre | AW4: Kg/Ad | AX4: Top Sayısı | AZ4: Tarih | BA4: Metre | BB4: Kg/Ad | BC4: Top Sayısı | BE4: Tarih | BF4: Metre | BG4: Kg/Ad | BH4: Top Sayısı | BJ4: Tarih | BK4: Metre | BL4: Kg/Ad | BM4: Top Sayısı
B5: Ürün Adı:
B6: Renk:
B7: Kumaş Eni:
B8: Sipariş Mt/Ad:
B9: Üretilen Metre | D9: =+H36+M36+R36+W36+AB36+AG36+AL36+AQ36+AV36+BA36+BF36+BK36 -> 0
B10: Üretilen Kg/Ad | D10: =+I36+N36+S36+X36+AC36+AH36+AM36+AR36+AW36+BB36+BG36+BL36 -> 0
B11: Üretilen Top Sayısı | D11: =+J36+O36+T36+Y36+AD36+AI36+AN36+AS36+AX36+BC36+BH36+BM36 -> 0
B12: Sevk Metre | D12: =BT39 -> 0
B13: Sevk Kg/Ad | D13: =BU39 -> 0
B14: Sevk Top Sayısı | D14: =BV39 -> 0
B15: Stok Metre | D15: =D9-D12 -> 0
B16: Stok Kg/Ad | D16: =D10-D13 -> 0
B17: Stok Top Sayısı | D17: =D11-D14 -> 0
B19: Üretim Durumu | D19: =D9/D8 -> #DIV/0!
G36: Toplam | H36: =SUM(H5:H35) -> 0 | I36: =SUM(I5:I35) -> 0 | J36: =SUM(J5:J35) -> 0 | L36: Toplam | M36: =SUM(M5:M35) -> 0 | N36: =SUM(N5:N35) -> 0 | O36: =SUM(O5:O35) -> 0 | Q36: Toplam | R36: =SUM(R5:R35) -> 0 | S36: =SUM(S5:S35) -> 0 | T36: =SUM(T5:T35) -> 0 | V36: Toplam | W36: =SUM(W5:W35) -> 0 | X36: =SUM(X5:X35) -> 0 | Y36: =SUM(Y5:Y35) -> 0 | AA36: Toplam | AB36: =SUM(AB5:AB35) -> 0 | AC36: =SUM(AC5:AC35) -> 0 | AD36: =SUM(AD5:AD35) -> 0 | AF36: Toplam | AG36: =SUM(AG5:AG35) -> 0 | AH36: =SUM(AH5:AH35) -> 0 | AI36: =SUM(AI5:AI35) -> 0 | AK36: Toplam | AL36: =SUM(AL5:AL35) -> 0 | AM36: =SUM(AM5:AM35) -> 0 | AN36: =SUM(AN5:AN35) -> 0 | AP36: Toplam | AQ36: =SUM(AQ5:AQ35) -> 0 | AR36: =SUM(AR5:AR35) -> 0 | AS36: =SUM(AS5:AS35) -> 0 | AU36: Toplam | AV36: =SUM(AV5:AV35) -> 0 | AW36: =SUM(AW5:AW35) -> 0 | AX36: =SUM(AX5:AX35) -> 0 | AZ36: Toplam | BA36: =SUM(BA5:BA35) -> 0 | BB36: =SUM(BB5:BB35) -> 0 | BC36: =SUM(BC5:BC35) -> 0 | BE36: Toplam | BF36: =SUM(BF5:BF35) -> 0 | BG36: =SUM(BG5:BG35) -> 0 | BH36: =SUM(BH5:BH35) -> 0 | BJ36: Toplam | BK36: =SUM(BK5:BK35) -> 0 | BL36: =SUM(BL5:BL35) -> 0 | BM36: =SUM(BM5:BM35) -> 0
BR39: Toplam | BT39: =SUM(BT5:BT36) -> 0 | BU39: =SUM(BU5:BU36) -> 0 | BV39: =SUM(BV5:BV36) -> 0

Sheet No.12
B2: Ürün Kodu: | G2: ÜRETİM VERİLERİ | BR2: SEVK VERİLERİ
B3: Sipariş No: | D3: ='SİPARİŞ FORMU'!C4 -> 0 | BR3: Tarih | BS3: Sevk yeri | BT3: Sevk Metre | BU3: Sevk Ad/Kg | BV3: Sevk Top Sayısı | BW3: Çeki Listesi | BX3: Açıklama
B4: Müşteri: | D4: ='SİPARİŞ FORMU'!C5 -> 0 | G4: Tarih | H4: Metre | I4: Kg/Ad | J4: Top Sayısı | L4: Tarih | M4: Metre | N4: Kg/Ad | O4: Top Sayısı | Q4: Tarih | R4: Metre | S4: Kg/Ad | T4: Top Sayısı | V4: Tarih | W4: Metre | X4: Kg/Ad | Y4: Top Sayısı | AA4: Tarih | AB4: Metre | AC4: Kg/Ad | AD4: Top Sayısı | AF4: Tarih | AG4: Metre | AH4: Kg/Ad | AI4: Top Sayısı | AK4: Tarih | AL4: Metre | AM4: Kg/Ad | AN4: Top Sayısı | AP4: Tarih | AQ4: Metre | AR4: Kg/Ad | AS4: Top Sayısı | AU4: Tarih | AV4: Metre | AW4: Kg/Ad | AX4: Top Sayısı | AZ4: Tarih | BA4: Metre | BB4: Kg/Ad | BC4: Top Sayısı | BE4: Tarih | BF4: Metre | BG4: Kg/Ad | BH4: Top Sayısı | BJ4: Tarih | BK4: Metre | BL4: Kg/Ad | BM4: Top Sayısı
B5: Ürün Adı:
B6: Renk:
B7: Kumaş Eni:
B8: Sipariş Mt/Ad:
B9: Üretilen Metre | D9: =+H36+M36+R36+W36+AB36+AG36+AL36+AQ36+AV36+BA36+BF36+BK36 -> 0
B10: Üretilen Kg/Ad | D10: =+I36+N36+S36+X36+AC36+AH36+AM36+AR36+AW36+BB36+BG36+BL36 -> 0
B11: Üretilen Top Sayısı | D11: =+J36+O36+T36+Y36+AD36+AI36+AN36+AS36+AX36+BC36+BH36+BM36 -> 0
B12: Sevk Metre | D12: =BT39 -> 0
B13: Sevk Kg/Ad | D13: =BU39 -> 0
B14: Sevk Top Sayısı | D14: =BV39 -> 0
B15: Stok Metre | D15: =D9-D12 -> 0
B16: Stok Kg/Ad | D16: =D10-D13 -> 0
B17: Stok Top Sayısı | D17: =D11-D14 -> 0
B19: Üretim Durumu | D19: =D9/D8 -> #DIV/0!
G36: Toplam | H36: =SUM(H5:H35) -> 0 | I36: =SUM(I5:I35) -> 0 | J36: =SUM(J5:J35) -> 0 | L36: Toplam | M36: =SUM(M5:M35) -> 0 | N36: =SUM(N5:N35) -> 0 | O36: =SUM(O5:O35) -> 0 | Q36: Toplam | R36: =SUM(R5:R35) -> 0 | S36: =SUM(S5:S35) -> 0 | T36: =SUM(T5:T35) -> 0 | V36: Toplam | W36: =SUM(W5:W35) -> 0 | X36: =SUM(X5:X35) -> 0 | Y36: =SUM(Y5:Y35) -> 0 | AA36: Toplam | AB36: =SUM(AB5:AB35) -> 0 | AC36: =SUM(AC5:AC35) -> 0 | AD36: =SUM(AD5:AD35) -> 0 | AF36: Toplam | AG36: =SUM(AG5:AG35) -> 0 | AH36: =SUM(AH5:AH35) -> 0 | AI36: =SUM(AI5:AI35) -> 0 | AK36: Toplam | AL36: =SUM(AL5:AL35) -> 0 | AM36: =SUM(AM5:AM35) -> 0 | AN36: =SUM(AN5:AN35) -> 0 | AP36: Toplam | AQ36: =SUM(AQ5:AQ35) -> 0 | AR36: =SUM(AR5:AR35) -> 0 | AS36: =SUM(AS5:AS35) -> 0 | AU36: Toplam | AV36: =SUM(AV5:AV35) -> 0 | AW36: =SUM(AW5:AW35) -> 0 | AX36: =SUM(AX5:AX35) -> 0 | AZ36: Toplam | BA36: =SUM(BA5:BA35) -> 0 | BB36: =SUM(BB5:BB35) -> 0 | BC36: =SUM(BC5:BC35) -> 0 | BE36: Toplam | BF36: =SUM(BF5:BF35) -> 0 | BG36: =SUM(BG5:BG35) -> 0 | BH36: =SUM(BH5:BH35) -> 0 | BJ36: Toplam | BK36: =SUM(BK5:BK35) -> 0 | BL36: =SUM(BL5:BL35) -> 0 | BM36: =SUM(BM5:BM35) -> 0
BR39: Toplam | BT39: =SUM(BT5:BT36) -> 0 | BU39: =SUM(BU5:BU36) -> 0 | BV39: =SUM(BV5:BV36) -> 0

Sheet No.13
B2: Ürün Kodu: | G2: ÜRETİM VERİLERİ | BR2: SEVK VERİLERİ
B3: Sipariş No: | D3: ='SİPARİŞ FORMU'!C4 -> 0 | BR3: Tarih | BS3: Sevk yeri | BT3: Sevk Metre | BU3: Sevk Ad/Kg | BV3: Sevk Top Sayısı | BW3: Çeki Listesi | BX3: Açıklama
B4: Müşteri: | D4: ='SİPARİŞ FORMU'!C5 -> 0 | G4: Tarih | H4: Metre | I4: Kg/Ad | J4: Top Sayısı | L4: Tarih | M4: Metre | N4: Kg/Ad | O4: Top Sayısı | Q4: Tarih | R4: Metre | S4: Kg/Ad | T4: Top Sayısı | V4: Tarih | W4: Metre | X4: Kg/Ad | Y4: Top Sayısı | AA4: Tarih | AB4: Metre | AC4: Kg/Ad | AD4: Top Sayısı | AF4: Tarih | AG4: Metre | AH4: Kg/Ad | AI4: Top Sayısı | AK4: Tarih | AL4: Metre | AM4: Kg/Ad | AN4: Top Sayısı | AP4: Tarih | AQ4: Metre | AR4: Kg/Ad | AS4: Top Sayısı | AU4: Tarih | AV4: Metre | AW4: Kg/Ad | AX4: Top Sayısı | AZ4: Tarih | BA4: Metre | BB4: Kg/Ad | BC4: Top Sayısı | BE4: Tarih | BF4: Metre | BG4: Kg/Ad | BH4: Top Sayısı | BJ4: Tarih | BK4: Metre | BL4: Kg/Ad | BM4: Top Sayısı
B5: Ürün Adı:
B6: Renk:
B7: Kumaş Eni:
B8: Sipariş Mt/Ad:
B9: Üretilen Metre | D9: =+H36+M36+R36+W36+AB36+AG36+AL36+AQ36+AV36+BA36+BF36+BK36 -> 0
B10: Üretilen Kg/Ad | D10: =+I36+N36+S36+X36+AC36+AH36+AM36+AR36+AW36+BB36+BG36+BL36 -> 0
B11: Üretilen Top Sayısı | D11: =+J36+O36+T36+Y36+AD36+AI36+AN36+AS36+AX36+BC36+BH36+BM36 -> 0
B12: Sevk Metre | D12: =BT39 -> 0
B13: Sevk Kg/Ad | D13: =BU39 -> 0
B14: Sevk Top Sayısı | D14: =BV39 -> 0
B15: Stok Metre | D15: =D9-D12 -> 0
B16: Stok Kg/Ad | D16: =D10-D13 -> 0
B17: Stok Top Sayısı | D17: =D11-D14 -> 0
B19: Üretim Durumu | D19: =D9/D8 -> #DIV/0!
